Workbook
Name _Ref94102448: IIS_Costs!$B$3
Name _Ref94103649: IIS_Costs!$B$14

Sheet Legend
A1: OMNIA Model
A2: Document type: | B2: BY and NewTech Template
A3: Region: | B3: Global
A4: Sector: | B4: Industry - Detailed sectors | C4: IND
A5: Base-year | B5: 2019
A6: Developer: | B6: UCL
A7: Version: | B7: 0.4
A8: Date: | B8: =TODAY() -> 46163
A9: Document description: | B9: This template holds the structure of the Final Energy Consumption in the Industrial sectors - Industry Sector
A12: Tab colour legend
B13: VEDA-TIMES data input tables
B14: Raw input data
B15: Processed raw input data
B16: EnergyBalance
A18: Table of contents
A19: Sheet | B19: Description
A20: Commodities | B20: Veda inputs: Definition of sector commodities
A21: EnergyBalance | B21: Industry energy balance
A22: Inputs_BY IIS | B22: Processing of energy balance data for input into BY template
A23: IIS_BY Techs | B23: Veda inputs: Characterization of IIS base-year technologies
A24: IIS_New Techs | B24: Veda inputs: Characterization of IIS new technologies
A25: IIS_Prod | B25: Steel production statistics (PIOLab)
A26: IIS_Capacity | B26: Steel plant capacity (Global Energy Monitor)
A27: IIS_Costs | B27: Steel production technology costs
A28: Inputs_BY INM | B28: Processing of energy balance data for input into BY template
A29: Inputs_NT INM | B29: New tech data for non-cement technologies
A30: INM_BY Techs | B30: Veda inputs: Characterization of INM base-year technologies
... A35: Cem_NewTechs | B35: Cement production cost estimates
A36: IAL_INF_Techs
A37: INF_Commodities
A38: INF_BY | B38: Veda inputs: Characterization of INF base-year technologies
A39: INF_NewTech | B39: Veda inputs: Characterization of INF new technologies
A40: INF_Data
A44: Conversion factors
A45: EUR2015 | B45: =1.0778*1.0599 -> 1.1423602 | C45: USD2021
A46: USD2019 | B46: 1.06 | C46: USD2021
A47: EUR2022 | B47: 0.88346756 | C47: EUR2019
A48: EUR2019 | B48: 1.1234 | C48: USD2019
A49: GBP2017 | B49: 1.29 | C49: USD2017
A50: EUR2015 | B50: 1.05 | C50: EUR2019
...

Sheet LOG
A2: LOG TABLE
A3: Date | B3: TAB | C3: CELL(s) | D3: Description of the change
A4: 45784 | B4: IIS_BY Techs | C4: AF29 | D4: Round very small number for INDELC in MEA to 0
A5: 45785 | B5: Inputs_NT INM | C5: T460-T462 | D5: Change INDELC share to 100% from 0%
A6: 45785 | B6: Inputs_NT INM | C6: T472,T484,T496 | D6: Change INDELC share to 100% from 0%
A7: 45785 | B7: INF_Data | C7: G170-AH170 | D7: Rounded primary IAL demands to minimum 1kt
A8: 45785 | B8: INF_Data | C8: G229-AH229 | D8: Rounded secondary IAL demands to minimum 1kt
A9: 45790 | B9: IIS_BY Techs | C9: J34-AK34 | D9: Corrected formula to point to correct values
A10: 45790 | B10: Inputs_BY INM | C10: E128-AF128, E147-AF147 | D10: Electricity intensity factors corrected to account for assumed split between dry and wet kilns
A11: 45790 | B11: Inputs_BY INM | C11: E121:AF135 & E140:AF154 | D11: Calculations adjusted slightly to ensure full calibration, using the clinker production value in row 35, not row 31
A12: 45814 | B12: Inputs_BY INM | C12: E128-AF128, E147-AF147 | D12: Electricity intensity factors corrected to factor in clinker (not cement) production
A13: 45819 | B13: INF_Data | C13: G232-AH232 | D13: Updated regional secondary aluminium production in base year to align with ENGAGE. Only minor changes
A14: 45831 | B14: INF_Data | C14: Rows 437-449 | D14: Add new/adjust aluminium scrap cost data
A15: 45831 | B15: INF_BY | C15: F147-AI147 | D15: Add ACT_COST for aluminium scrap
... A23: 46007 | B23: IIS_New Techs | C23: G17:G20 | D23: Initial year for steel techs with CCS 2035 instead of 2030
A24: 46013 | B24: EnergyBalance | D24: Nigeria biomass consumption updated
A25: 46106 | B25: Inputs_NT INM | D25: Enabled (0%->100%) OIL techs in Table 16 fuel shares for ASO - previously set to 100%

Sheet Commodities
B1: Commodities definition
B3: ~FI_Comm
B4: Csets | C4: CommName | D4: CommDesc | E4: Unit | F4: LimType | G4: CTSLvl | H4: PeakTS | I4: Ctype
B5: *Commodity set | C5: Commodity name | D5: Description | E5: Unit of measure
B6: NRG | C6: =Legend!B96 -> INDBFG | D6: =Legend!A96&" ("&Legend!$C$4&")" -> Blast furnace gas (IND) | E6: PJ
B7: NRG | C7: =Legend!B97 -> INDBGS | D7: =Legend!A97&" ("&Legend!$C$4&")" -> Biogas (IND) | E7: PJ
B8: NRG | C8: =Legend!B98 -> INDBIO | D8: =Legend!A98&" ("&Legend!$C$4&")" -> Biomass (IND) | E8: PJ
B9: NRG | C9: =Legend!B99 -> INDBLQ | D9: =Legend!A99&" ("&Legend!$C$4&")" -> Bioliquids (IND) | E9: PJ
B10: NRG | C10: =Legend!B100 -> INDCOA | D10: =Legend!A100&" ("&Legend!$C$4&")" -> Coal (IND) | E10: PJ
B11: NRG | C11: =Legend!B101 -> INDCOG | D11: =Legend!A101&" ("&Legend!$C$4&")" -> Coke oven gas (IND) | E11: PJ
B12: NRG | C12: =Legend!B102 -> INDCOK | D12: =Legend!A102&" ("&Legend!$C$4&")" -> Coke oven coke (IND) | E12: PJ
B13: NRG | C13: =Legend!B103 -> INDELC | D13: =Legend!A103&" ("&Legend!$C$4&")" -> Electricity (IND) | E13: PJ | G13: DayNite | I13: ELC
B14: NRG | C14: =Legend!B104 -> INDGAS | D14: =Legend!A104&" ("&Legend!$C$4&")" -> Natural gas (IND) | E14: PJ
B15: NRG | C15: =Legend!B105 -> INDHET | D15: =Legend!A105&" ("&Legend!$C$4&")" -> Heat (IND) | E15: PJ | G15: DayNite | I15: LTHEAT
B16: NRG | C16: =Legend!B106 -> INDLPG | D16: =Legend!A106&" ("&Legend!$C$4&")" -> LPG (IND) | E16: PJ
B17: NRG | C17: =Legend!B107 -> INDOIL | D17: =Legend!A107&" ("&Legend!$C$4&")" -> Oil (IND) | E17: PJ
B18: NRG | C18: =Legend!B108 -> INDGEO | D18: =Legend!A108&" ("&Legend!$C$4&")" -> Geothermal (IND) | E18: PJ
B19: NRG | C19: =Legend!B109 -> INDCSP | D19: =Legend!A109&" ("&Legend!$C$4&")" -> Concentrated solar power (IND) | E19: PJ
B20: NRG | C20: =Legend!B110 -> INDWAS | D20: =Legend!A110&" ("&Legend!$C$4&")" -> Waste (IND) | E20: PJ
B21: NRG | C21: =Legend!B111 -> INDH2G | D21: =Legend!A111&" ("&Legend!$C$4&")" -> Hydrogen (IND) | E21: PJ
B22: NRG | C22: =Legend!B112 -> INDH2B | D22: =Legend!A112&" ("&Legend!$C$4&")" -> Natural gas H2 blend (IND) | E22: PJ
B23: ENV | C23: =Legend!B115 -> INDCO2e | D23: =Legend!A115&" emissions ("&Legend!$C$4&")" -> CO2eq emissions (IND) | E23: kt
B24: ENV | C24: =Legend!B116 -> INDCO2 | D24: =Legend!A116&" emissions ("&Legend!$C$4&")" -> CO2 emissions (IND) | E24: kt
B25: ENV | C25: =Legend!B117 -> INDCH4 | D25: =Legend!A117&" emissions ("&Legend!$C$4&")" -> CH4 emissions (IND) | E25: kt
B26: ENV | C26: =Legend!B118 -> INDN2O | D26: =Legend!A118&" emissions ("&Legend!$C$4&")" -> N2O emissions (IND) | E26: kt
B27: ENV | C27: =Legend!B119 -> INDCO2p | D27: =Legend!A119&" emissions ("&Legend!$C$4&")" -> CO2 process emissions (IND) | E27: kt
B28: ENV | C28: =Legend!B120 -> INDCO2c | D28: =Legend!A120&" emissions ("&Legend!$C$4&")" -> CO2 process emissions (IND) | E28: kt

Sheet EnergyBalance
A2: Industry Sector Final Energy Balances | G2: Source: | H2: Omnia_Energy_Balance_NEW_29_4_2024.xlsx
A4: ** All sectors are included here as this workbook will include multiple sectors**
A7: Subsector | B7: Subsector extended | C7: Primary energy commoditiy | D7: Unit | E7: AFE | F7: AFN | G7: AFW | H7: AFZ | I7: ANZ | J7: ASC | K7: ASE | L7: ASO | M7: BRA | N7: CAN | O7: CHL | P7: CHN | Q7: ENE | R7: ENW | S7: EUE | T7: EUM | U7: EUW | V7: IDN | W7: IND | X7: JPN | Y7: LAM | Z7: MDA | AA7: MEA | AB7: MEX | AC7: NIG | AD7: RUS | AE7: SKT | AF7: USA
A8: ICH | B8: Chemical and petrochemical | C8: INDBFG | D8: TJ | E8: 0 | F8: 0 | G8: 0 | H8: 0 | I8: 0 | J8: 0 | K8: 0 | L8: 0 | M8: 0 | N8: 0 | O8: 0 | P8: 3872 | Q8: 0 | R8: 312 | S8: 0 | T8: 0 | U8: 0 | V8: 0 | W8: 0 | X8: 4355 | Y8: 0 | Z8: 0 | AA8: 0 | AB8: 0 | AC8: 0 | AD8: 0 | AE8: 0 | AF8: 0
A9: ICH | B9: Chemical and petrochemical | C9: INDBGS | D9: TJ | E9: 0 | F9: 0 | G9: 0 | H9: 0 | I9: 0 | J9: 0 | K9: 25868 | L9: 0 | M9: 0 | N9: 0 | O9: 0 | P9: 0 | Q9: 20 | R9: 231 | S9: 110 | T9: 288 | U9: 1049 | V9: 0 | W9: 0 | X9: 0 | Y9: 0 | Z9: 0 | AA9: 0 | AB9: 0 | AC9: 0 | AD9: 0 | AE9: 329 | AF9: 263
A10: ICH | B10: Chemical and petrochemical | C10: INDBIO | D10: TJ | E10: 0 | F10: 209 | G10: 0 | H10: 0 | I10: 805 | J10: 0 | K10: 14207 | L10: 0 | M10: 2409 | N10: 0 | O10: 0 | P10: 33478 | Q10: 1427 | R10: 6599 | S10: 3069 | T10: 5215 | U10: 5060 | V10: 1203 | W10: 0 | X10: 1198 | Y10: 131 | Z10: 0 | AA10: 0 | AB10: 0 | AC10: 0 | AD10: 937 | AE10: 42 | AF10: 2981
A11: ICH | B11: Chemical and petrochemical | C11: INDBLQ | D11: TJ | E11: 0 | F11: 0 | G11: 0 | H11: 0 | I11: 0 | J11: 0 | K11: 0 | L11: 0 | M11: 44 | N11: 0 | O11: 0 | P11: 0 | Q11: 0 | R11: 72 | S11: 0 | T11: 157 | U11: 158 | V11: 19 | W11: 0 | X11: 0 | Y11: 0 | Z11: 0 | AA11: 0 | AB11: 0 | AC11: 0 | AD11: 0 | AE11: 0 | AF11: 1175
A12: ICH | B12: Chemical and petrochemical | C12: INDCOA | D12: TJ | E12: 0 | F12: 0 | G12: 0 | H12: 4796 | I12: 6396 | J12: 533 | K12: 2454 | L12: 0 | M12: 7304 | N12: 0 | O12: 0 | P12: 116413 | Q12: 838 | R12: 9564 | S12: 66719 | T12: 18264 | U12: 11731 | V12: 101851 | W12: 30912 | X12: 111548 | Y12: 3673 | Z12: 24018 | AA12: 0 | AB12: 0 | AC12: 0 | AD12: 7332 | AE12: 3070 | AF12: 66661
A13: ICH | B13: Chemical and petrochemical | C13: INDCOG | D13: TJ | E13: 0 | F13: 0 | G13: 0 | H13: 0 | I13: 0 | J13: 0 | K13: 0 | L13: 0 | M13: 0 | N13: 0 | O13: 0 | P13: 150491 | Q13: 0 | R13: 0 | S13: 671 | T13: 0 | U13: 3394 | V13: 0 | W13: 0 | X13: 27491 | Y13: 0 | Z13: 0 | AA13: 0 | AB13: 0 | AC13: 0 | AD13: 0 | AE13: 0 | AF13: 0
A14: ICH | B14: Chemical and petrochemical | C14: INDCOK | D14: TJ | E14: 0 | F14: 0 | G14: 0 | H14: 0 | I14: 469 | J14: 9110 | K14: 0 | L14: 0 | M14: 0 | N14: 0 | O14: 0 | P14: 699489 | Q14: 0 | R14: 1370 | S14: 2292 | T14: 671 | U14: 790 | V14: 0 | W14: 0 | X14: 1115 | Y14: 14 | Z14: 0 | AA14: 0 | AB14: 0 | AC14: 0 | AD14: 789 | AE14: 0 | AF14: 0
A15: ICH | B15: Chemical and petrochemical | C15: INDELC | D15: TJ | E15: 0 | F15: 12999 | G15: 1909 | H15: 31764 | I15: 15540 | J15: 35450 | K15: 51209 | L15: 0 | M15: 75578 | N15: 75244 | O15: 130 | P15: 1953857 | Q15: 32295 | R15: 91866 | S15: 83617 | T15: 164051 | U15: 349051 | V15: 23501 | W15: 0 | X15: 202335 | Y15: 24125 | Z15: 24849 | AA15: 35292 | AB15: 20678 | AC15: 0 | AD15: 171581 | AE15: 190670 | AF15: 448024
A16: ICH | B16: Chemical and petrochemical | C16: INDGAS | D16: TJ | E16: 0 | F16: 6872 | G16: 0 | H16: 46571 | I16: 84406 | J16: 99351 | K16: 66636 | L16: 0 | M16: 76880 | N16: 146119 | O16: 5934 | P16: 1240400 | Q16: 17746 | R16: 81196 | S16: 84753 | T16: 284828 | U16: 382352 | V16: 39902 | W16: 0 | X16: 82509 | Y16: 72722 | Z16: 61902 | AA16: 706309 | AB16: 108561 | AC16: 17601 | AD16: 352442 | AE16: 37425 | AF16: 2285644
A17: ICH | B17: Chemical and petrochemical | C17: INDHET | D17: TJ | E17: 0 | F17: 0 | G17: 0 | H17: 0 | I17: 0 | J17: 13945 | K17: 0 | L17: 0 | M17: 0 | N17: 10533 | O17: 0 | P17: 1451781 | Q17: 52441 | R17: 12193 | S17: 50107 | T17: 83809 | U17: 191417 | V17: 0 | W17: 0 | X17: 0 | Y17: 0 | Z17: 0 | AA17: 0 | AB17: 0 | AC17: 0 | AD17: 518995 | AE17: 86325 | AF17: 122317
A18: ICH | B18: Chemical and petrochemical | C18: INDLPG | D18: TJ | E18: 0 | F18: 1986 | G18: 0 | H18: 0 | I18: 0 | J18: 477 | K18: 56025 | L18: 0 | M18: 8876 | N18: 0 | O18: 0 | P18: 427300 | Q18: 741 | R18: 3163 | S18: 14021 | T18: 4344 | U18: 49361 | V18: 1215 | W18: 0 | X18: 22356 | Y18: 173 | Z18: 94 | AA18: 7816 | AB18: 473 | AC18: 0 | AD18: 195735 | AE18: 9674 | AF18: 4532
A19: ICH | B19: Chemical and petrochemical | C19: INDOIL | D19: TJ | E19: 0 | F19: 1806 | G19: 979 | H19: 265 | I19: 4471 | J19: 1596 | K19: 103233 | L19: 0 | M19: 99262 | N19: 939 | O19: 0 | P19: 230833 | Q19: 2603 | R19: 16586 | S19: 65936 | T19: 29816 | U19: 163150 | V19: 14807 | W19: 522444 | X19: 339577 | Y19: 9573 | Z19: 415 | AA19: 11112 | AB19: 8703 | AC19: 0 | AD19: 199657 | AE19: 22505 | AF19: 64628
... A100: IOI | B100: Other industries | C100: INDWAS | D100: TJ | E100: 0 | F100: 0 | G100: 28 | H100: 0 | I100: 102 | J100: 0 | K100: 2536 | L100: 0 | M100: 0 | N100: 0 | O100: 0 | P100: 0 | Q100: 0 | R100: 2259 | S100: 1350 | T100: 1863 | U100: 18583 | V100: 0 | W100: 0 | X100: 14610 | Y100: 524 | Z100: 18139 | AA100: 0 | AB100: 0 | AC100: 0 | AD100: 50558 | AE100: 27480 | AF100: 8864
A103: **Other industries is further broken down into further subsectors below [based on file Other_industries_breakdown]
A106: Subsector | B106: Subsector extended | C106: Primary energy commoditiy | D106: Unit | E106: AFE | F106: AFN | G106: AFW | H106: AFZ | I106: ANZ | J106: ASC | K106: ASE | L106: ASO | M106: BRA | N106: CAN | O106: CHL | P106: CHN | Q106: ENE | R106: ENW | S106: EUE | T106: EUM | U106: EUW | V106: IDN | W106: IND | X106: JPN | Y106: LAM | Z106: MDA | AA106: MEA | AB106: MEX | AC106: NIG | AD106: RUS | AE106: SKT | AF106: USA
A107: IPP | B107: Pulp and paper | C107: INDBFG | D107: TJ | E107: 0 | F107: 0 | G107: 0 | H107: 0 | I107: 0 | J107: 0 | K107: 0 | L107: 0 | M107: 0 | N107: 0 | O107: 0 | P107: 0 | Q107: 0 | R107: 0 | S107: 0 | T107: 0 | U107: 0 | V107: 0 | W107: 0 | X107: 0 | Y107: 0 | Z107: 0 | AA107: 0 | AB107: 0 | AC107: 0 | AD107: 0 | AE107: 0 | AF107: 0
A108: IPP | B108: Pulp and paper | C108: INDBGS | D108: TJ | E108: 0 | F108: 0 | G108: 0 | H108: 0 | I108: 24 | J108: 0 | K108: 0 | L108: 0 | M108: 0 | N108: 2384 | O108: 0 | P108: 0 | Q108: 0 | R108: 432 | S108: 214 | T108: 1380 | U108: 6490 | V108: 0 | W108: 0 | X108: 0 | Y108: 0 | Z108: 0 | AA108: 0 | AB108: 0 | AC108: 0 | AD108: 0 | AE108: 71 | AF108: 166
A109: IPP | B109: Pulp and paper | C109: INDBIO | D109: TJ | E109: 0 | F109: 0 | G109: 0 | H109: 0 | I109: 3804 | J109: 0 | K109: 12520 | L109: 0 | M109: 269175 | N109: 0 | O109: 0 | P109: 17361 | Q109: 94 | R109: 19586 | S109: 52923 | T109: 19229 | U109: 47954 | V109: 0 | W109: 0 | X109: 0 | Y109: 4636 | Z109: 0 | AA109: 0 | AB109: 0 | AC109: 363 | AD109: 200 | AE109: 497 | AF109: 1208840
A110: IPP | B110: Pulp and paper | C110: INDBLQ | D110: TJ | E110: 0 | F110: 0 | G110: 0 | H110: 0 | I110: 0 | J110: 0 | K110: 0 | L110: 0 | M110: 644 | N110: 0 | O110: 0 | P110: 0 | Q110: 0 | R110: 0 | S110: 0 | T110: 14 | U110: 510 | V110: 1 | W110: 0 | X110: 0 | Y110: 0 | Z110: 0 | AA110: 0 | AB110: 0 | AC110: 0 | AD110: 0 | AE110: 0 | AF110: 21226
A111: IPP | B111: Pulp and paper | C111: INDCOA | D111: TJ | E111: 0 | F111: 0 | G111: 0 | H111: 3062 | I111: 1779 | J111: 81 | K111: 453 | L111: 0 | M111: 5548 | N111: 0 | O111: 0 | P111: 0 | Q111: 17 | R111: 2742 | S111: 12594 | T111: 221 | U111: 18007 | V111: 0 | W111: 23957 | X111: 67833 | Y111: 15020 | Z111: 8793 | AA111: 0 | AB111: 0 | AC111: 0 | AD111: 1 | AE111: 0 | AF111: 42872
A112: IPP | B112: Pulp and paper | C112: INDCOG | D112: TJ | E112: 0 | F112: 0 | G112: 0 | H112: 0 | I112: 0 | J112: 0 | K112: 0 | L112: 0 | M112: 0 | N112: 0 | O112: 0 | P112: 0 | Q112: 0 | R112: 0 | S112: 0 | T112: 0 | U112: 0 | V112: 0 | W112: 0 | X112: 0 | Y112: 0 | Z112: 0 | AA112: 0 | AB112: 0 | AC112: 0 | AD112: 0 | AE112: 0 | AF112: 0
A113: IPP | B113: Pulp and paper | C113: INDCOK | D113: TJ | E113: 0 | F113: 0 | G113: 0 | H113: 0 | I113: 0 | J113: 0 | K113: 0 | L113: 0 | M113: 0 | N113: 0 | O113: 0 | P113: 0 | Q113: 0 | R113: 0 | S113: 0 | T113: 0 | U113: 0 | V113: 0 | W113: 0 | X113: 692 | Y113: 155 | Z113: 0 | AA113: 0 | AB113: 0 | AC113: 0 | AD113: 2 | AE113: 0 | AF113: 0
A114: IPP | B114: Pulp and paper | C114: INDELC | D114: TJ | E114: 0 | F114: 2010 | G114: 153 | H114: 4189 | I114: 18120 | J114: 1044 | K114: 10983 | L114: 0 | M114: 84362 | N114: 157442 | O114: 20663 | P114: 0 | Q114: 8412 | R114: 58643 | S114: 46620 | T114: 100908 | U114: 264159 | V114: 5684 | W114: 0 | X114: 144400 | Y114: 12931 | Z114: 13741 | AA114: 0 | AB114: 12553 | AC114: 0 | AD114: 74277 | AE114: 45081 | AF114: 289778
A115: IPP | B115: Pulp and paper | C115: INDGAS | D115: TJ | E115: 0 | F115: 2396 | G115: 0 | H115: 605 | I115: 13168 | J115: 2303 | K115: 11368 | L115: 0 | M115: 36524 | N115: 91874 | O115: 5687 | P115: 0 | Q115: 2876 | R115: 19931 | S115: 35007 | T115: 95493 | U115: 148349 | V115: 0 | W115: 0 | X115: 33026 | Y115: 5546 | Z115: 9092 | AA115: 0 | AB115: 34247 | AC115: 0 | AD115: 26042 | AE115: 12681 | AF115: 358012
A116: IPP | B116: Pulp and paper | C116: INDHET | D116: TJ | E116: 0 | F116: 0 | G116: 0 | H116: 0 | I116: 0 | J116: 727 | K116: 0 | L116: 0 | M116: 0 | N116: 4980 | O116: 0 | P116: 0 | Q116: 13044 | R116: 2579 | S116: 7024 | T116: 44303 | U116: 48204 | V116: 0 | W116: 0 | X116: 0 | Y116: 0 | Z116: 0 | AA116: 0 | AB116: 0 | AC116: 0 | AD116: 203739 | AE116: 11389 | AF116: 20016
A117: IPP | B117: Pulp and paper | C117: INDLPG | D117: TJ | E117: 0 | F117: 8 | G117: 0 | H117: 0 | I117: 113 | J117: 14 | K117: 311 | L117: 0 | M117: 2902 | N117: 0 | O117: 546 | P117: 1276 | Q117: 56 | R117: 94 | S117: 405 | T117: 1425 | U117: 4213 | V117: 273 | W117: 0 | X117: 2936 | Y117: 156 | Z117: 0 | AA117: 0 | AB117: 281 | AC117: 0 | AD117: 135 | AE117: 238 | AF117: 1410
A118: IPP | B118: Pulp and paper | C118: INDOIL | D118: TJ | E118: 0 | F118: 816 | G118: 0 | H118: 175 | I118: 2007 | J118: 136 | K118: 6462 | L118: 0 | M118: 17855 | N118: 2166 | O118: 2395 | P118: 16131 | Q118: 828 | R118: 2573 | S118: 1957 | T118: 5412 | U118: 10114 | V118: 188 | W118: 0 | X118: 34659 | Y118: 1341 | Z118: -66 | AA118: 0 | AB118: 9487 | AC118: 0 | AD118: 10059 | AE118: 517 | AF118: 3574
... A215: INS | B215: Not elsewhere specified (industry) | C215: INDWAS | D215: TJ | E215: 0 | F215: 0 | G215: 28 | H215: 0 | I215: 0 | J215: 0 | K215: 2536 | L215: 0 | M215: 0 | N215: 0 | O215: 0 | P215: 0 | Q215: 0 | R215: 506 | S215: 13 | T215: 1198 | U215: 135 | V215: 0 | W215: 0 | X215: 0 | Y215: 241 | Z215: 5662 | AA215: 0 | AB215: 0 | AC215: 0 | AD215: 146 | AE215: 5012 | AF215: 2524
A220: ** Whilst blast furnace is a conversion sector in the energy balance, it has been included in the Iron and steel sector due to being an integral part of the BF-BOF process**
A222: Blast Furnace - Transformation Inputs
AI223: INDCOA | AJ223: =SUMIFS(AF8:AF100,C8:C100,AI223) -> 455517
B225: Subsector | C225: Primary energy commoditiy | D225: Unit | E225: AFE | F225: AFN | G225: AFW | H225: AFZ | I225: ANZ | J225: ASC | K225: ASE | L225: ASO | M225: BRA | N225: CAN | O225: CHL | P225: CHN | Q225: ENE | R225: ENW | S225: EUE | T225: EUM | U225: EUW | V225: IDN | W225: IND | X225: JPN | Y225: LAM | Z225: MDA | AA225: MEA | AB225: MEX | AC225: NIG | AD225: RUS | AE225: SKT | AF225: USA
B226: Blast furnace | C226: UPSBIO | D226: TJ | E226: 0 | F226: 0 | G226: 0 | H226: 0 | I226: 0 | J226: 0 | K226: 0 | L226: 0 | M226: 0 | N226: 0 | O226: 0 | P226: 0 | Q226: 0 | R226: 0 | S226: 0 | T226: 0 | U226: -24 | V226: 0 | W226: 0 | X226: 0 | Y226: 0 | Z226: 0 | AA226: 0 | AB226: 0 | AC226: 0 | AD226: 0 | AE226: 0 | AF226: 0
B227: Blast furnace | C227: UPSCOA | D227: TJ | E227: 0 | F227: -508 | G227: 0 | H227: 0 | I227: -1642 | J227: 0 | K227: 0 | L227: 0 | M227: 0 | N227: 0 | O227: 0 | P227: 0 | Q227: -6389 | R227: -30162 | S227: -30101 | T227: -94630 | U227: -241100 | V227: -7779 | W227: -68539 | X227: -349069 | Y227: 0 | Z227: -27762 | AA227: 0 | AB227: 0 | AC227: 0 | AD227: -67280 | AE227: -202209 | AF227: -26858
B228: Blast furnace | C228: UPSCOK | D228: TJ | E228: 0 | F228: -16215 | G228: 0 | H228: -45329 | I228: -52807 | J228: -56573 | K228: -4858 | L228: 0 | M228: 0 | N228: -52955 | O228: -8024 | P228: -9761909 | Q228: -257714 | R228: -62348 | S228: -192455 | T228: -162461 | U228: -461002 | V228: 0 | W228: -1020695 | X228: -812199 | Y228: -20353 | Z228: -95610 | AA228: -35292 | AB228: -39121 | AC228: 0 | AD228: -478411 | AE228: -413916 | AF228: -239829
B229: Blast furnace | C229: UPSGAS | D229: TJ | E229: 0 | F229: 0 | G229: 0 | H229: 0 | I229: 0 | J229: 0 | K229: 0 | L229: 0 | M229: 0 | N229: 0 | O229: 0 | P229: 0 | Q229: 0 | R229: 0 | S229: -1181 | T229: 0 | U229: 0 | V229: 0 | W229: 0 | X229: 0 | Y229: 0 | Z229: 0 | AA229: 0 | AB229: 0 | AC229: 0 | AD229: 0 | AE229: 0 | AF229: 0
B230: Blast furnace | C230: UPSHFO | D230: TJ | E230: 0 | F230: 0 | G230: 0 | H230: 0 | I230: 0 | J230: -5074 | K230: 0 | L230: 0 | M230: 0 | N230: 0 | O230: 0 | P230: 0 | Q230: 0 | R230: 0 | S230: 0 | T230: 0 | U230: -1414 | V230: 0 | W230: 0 | X230: 0 | Y230: 0 | Z230: 0 | AA230: 0 | AB230: 0 | AC230: 0 | AD230: 0 | AE230: 0 | AF230: 0
...

Sheet Inputs_BY IIS
A2: ENERGY BALANCE - COKE OVENS / BF
A3: Source: UN energy balances - Omnia_Energy_Balance_NEW_29_4_2024.xlsx
A5: ** Blast furnace and coke ovens are key sectors associated with steel production. Coke ovens is actually modelled in upstream (as a transformation sector) but captured here to understand flows.
A7: Transformation Energy Use
A8: Subsector | B8: Primary energy commodity | D8: Unit | E8: AFE | F8: AFN | G8: AFW | H8: AFZ | I8: ANZ | J8: ASC | K8: ASE | L8: ASO | M8: BRA | N8: CAN | O8: CHL | P8: CHN | Q8: ENE | R8: ENW | S8: EUE | T8: EUM | U8: EUW | V8: IDN | W8: IND | X8: JPN | Y8: LAM | Z8: MDA | AA8: MEA | AB8: MEX | AC8: NIG | AD8: RUS | AE8: SKT | AF8: USA
A9: Blast furnace | B9: UPSBIO | D9: TJ | E9: =EnergyBalance!E226 -> 0 | F9: =EnergyBalance!F226 -> 0 | G9: =EnergyBalance!G226 -> 0 | H9: =EnergyBalance!H226 -> 0 | I9: =EnergyBalance!I226 -> 0 | J9: =EnergyBalance!J226 -> 0 | K9: =EnergyBalance!K226 -> 0 | L9: =EnergyBalance!L226 -> 0 | ... AF9: =EnergyBalance!AF226 -> 0
A10: Blast furnace | B10: UPSCOA | D10: TJ | E10: =EnergyBalance!E227 -> 0 | F10: =EnergyBalance!F227 -> -508 | G10: =EnergyBalance!G227 -> 0 | H10: =EnergyBalance!H227 -> 0 | I10: =EnergyBalance!I227 -> -1642 | J10: =EnergyBalance!J227 -> 0 | K10: =EnergyBalance!K227 -> 0 | L10: =EnergyBalance!L227 -> 0 | ... AF10: =EnergyBalance!AF227 -> -26858
A11: Blast furnace | B11: UPSCOK | D11: TJ | E11: =EnergyBalance!E228 -> 0 | F11: =EnergyBalance!F228 -> -16215 | G11: =EnergyBalance!G228 -> 0 | H11: =EnergyBalance!H228 -> -45329 | I11: =EnergyBalance!I228 -> -52807 | J11: =EnergyBalance!J228 -> -56573 | K11: =EnergyBalance!K228 -> -4858 | L11: =EnergyBalance!L228 -> 0 | ... AF11: =EnergyBalance!AF228 -> -239829
A12: Blast furnace | B12: UPSGAS | D12: TJ | E12: =EnergyBalance!E229 -> 0 | F12: =EnergyBalance!F229 -> 0 | G12: =EnergyBalance!G229 -> 0 | H12: =EnergyBalance!H229 -> 0 | I12: =EnergyBalance!I229 -> 0 | J12: =EnergyBalance!J229 -> 0 | K12: =EnergyBalance!K229 -> 0 | L12: =EnergyBalance!L229 -> 0 | ... AF12: =EnergyBalance!AF229 -> 0
A13: Blast furnace | B13: UPSHFO | D13: TJ | E13: =EnergyBalance!E230 -> 0 | F13: =EnergyBalance!F230 -> 0 | G13: =EnergyBalance!G230 -> 0 | H13: =EnergyBalance!H230 -> 0 | I13: =EnergyBalance!I230 -> 0 | J13: =EnergyBalance!J230 -> -5074 | K13: =EnergyBalance!K230 -> 0 | L13: =EnergyBalance!L230 -> 0 | ... AF13: =EnergyBalance!AF230 -> 0
A14: Blast furnace | B14: UPSOIL2 | D14: TJ | E14: =EnergyBalance!E231 -> 0 | F14: =EnergyBalance!F231 -> 0 | G14: =EnergyBalance!G231 -> 0 | H14: =EnergyBalance!H231 -> 0 | I14: =EnergyBalance!I231 -> 0 | J14: =EnergyBalance!J231 -> 0 | K14: =EnergyBalance!K231 -> 0 | L14: =EnergyBalance!L231 -> 0 | ... AF14: =EnergyBalance!AF231 -> 0
A16: Coke oven | B16: UPSCOA | D16: TJ | E16: 0 | F16: -14532 | G16: 0 | H16: -82420 | I16: -121746 | J16: -81877 | K16: 0 | L16: 0 | M16: -290360 | N16: -89166 | O16: -16142 | P16: -15039318 | Q16: -379416 | R16: -52836 | S16: -527878 | T16: -205725 | U16: -600926 | V16: -152300 | W16: -1349171 | X16: -1235859 | Y16: -106615 | Z16: -151056 | AA16: -63554 | AB16: -38083 | AC16: 0 | AD16: -1910106 | AE16: -650757 | AF16: -443072
A17: Coke oven | B17: UPSCOALIG | D17: TJ | E17: 0 | F17: 0 | G17: 0 | H17: 0 | I17: 0 | J17: 0 | K17: 0 | L17: 0 | M17: 0 | N17: 0 | O17: 0 | P17: 0 | Q17: 0 | R17: 0 | S17: 0 | T17: 0 | U17: -7860 | V17: 0 | W17: 0 | X17: 0 | Y17: 0 | Z17: 0 | AA17: 0 | AB17: 0 | AC17: 0 | AD17: 0 | AE17: 0 | AF17: 0
A18: Coke oven | B18: UPSGAS | D18: TJ | E18: 0 | F18: 0 | G18: 0 | H18: 0 | I18: 0 | J18: 0 | K18: 0 | L18: 0 | M18: 0 | N18: 0 | O18: 0 | P18: 0 | Q18: 0 | R18: -1002 | S18: 0 | T18: 0 | U18: 0 | V18: 0 | W18: 0 | X18: 0 | Y18: 0 | Z18: 0 | AA18: 0 | AB18: 0 | AC18: 0 | AD18: 0 | AE18: 0 | AF18: 0
A19: Coke oven | B19: UPSLPG | D19: TJ | E19: 0 | F19: 0 | G19: 0 | H19: 0 | I19: 0 | J19: 0 | K19: 0 | L19: 0 | M19: 0 | N19: 0 | O19: 0 | P19: 0 | Q19: 0 | R19: 0 | S19: 0 | T19: -1 | U19: 0 | V19: 0 | W19: 0 | X19: 0 | Y19: 0 | Z19: 0 | AA19: 0 | AB19: 0 | AC19: 0 | AD19: 0 | AE19: 0 | AF19: 0
A20: Coke oven | B20: UPSOIL2 | D20: TJ | E20: 0 | F20: 0 | G20: 0 | H20: 0 | I20: 0 | J20: 0 | K20: 0 | L20: 0 | M20: -49911 | N20: 0 | O20: 0 | P20: 0 | Q20: 0 | R20: 0 | S20: 0 | T20: 0 | U20: -12833 | V20: 0 | W20: 0 | X20: -15839 | Y20: 0 | Z20: 0 | AA20: 0 | AB20: 0 | AC20: 0 | AD20: 0 | AE20: 0 | AF20: 0
A21: Coke oven | B21: UPSWAS | D21: TJ | E21: 0 | F21: 0 | G21: 0 | H21: 0 | I21: 0 | J21: 0 | K21: 0 | L21: 0 | M21: 0 | N21: 0 | O21: 0 | P21: 0 | Q21: 0 | R21: 0 | S21: 0 | T21: 0 | U21: 0 | V21: 0 | W21: 0 | X21: -4872 | Y21: 0 | Z21: 0 | AA21: 0 | AB21: 0 | AC21: 0 | AD21: 0 | AE21: 0 | AF21: 0
A24: Transformation Energy Production
A25: Subsector | B25: Primary energy commoditiy | D25: Unit | E25: AFE | F25: AFN | G25: AFW | H25: AFZ | I25: ANZ | J25: ASC | K25: ASE | L25: ASO | M25: BRA | N25: CAN | O25: CHL | P25: CHN | Q25: ENE | R25: ENW | S25: EUE | T25: EUM | U25: EUW | V25: IDN | W25: IND | X25: JPN | Y25: LAM | Z25: MDA | AA25: MEA | AB25: MEX | AC25: NIG | AD25: RUS | AE25: SKT | AF25: USA
A26: Blast furnace | B26: UPSBFG | D26: TJ | E26: =EnergyBalance!E237 -> 0 | F26: =EnergyBalance!F237 -> 3350 | G26: =EnergyBalance!G237 -> 0 | H26: =EnergyBalance!H237 -> 18142 | I26: =EnergyBalance!I237 -> 23635 | J26: =EnergyBalance!J237 -> 17821 | K26: =EnergyBalance!K237 -> 2654 | L26: =EnergyBalance!L237 -> 0 | ... AF26: =EnergyBalance!AF237 -> 110352
A28: Coke oven | B28: UPSCOG | D28: TJ | E28: 0 | F28: 0 | G28: 0 | H28: 21130 | I28: 24923 | J28: 14455 | K28: 0 | L28: 0 | M28: 77379 | N28: 24338 | O28: 3550 | P28: 1788779 | Q28: 77882 | R28: 13522 | S28: 118747 | T28: 22973 | U28: 125698 | V28: 0 | W28: 205572 | X28: 300259 | Y28: 2526 | Z28: 36032 | AA28: 7973 | AB28: 8592 | AC28: 0 | AD28: 286443 | AE28: 152766 | AF28: 61173
A29: Coke oven | B29: UPSCOK | D29: TJ | E29: 0 | F29: 13122 | G29: 0 | H29: 55223 | I29: 79262 | J29: 67318 | K29: 0 | L29: 0 | M29: 261593 | N29: 64828 | O29: 12370 | P29: 13250539 | Q29: 301533 | R29: 39733 | S29: 408205 | T29: 163220 | U29: 495361 | V29: 125228 | W29: 1143599 | X29: 940192 | Y29: 83873 | Z29: 114729 | AA29: 52545 | AB29: 28614 | AC29: 0 | AD29: 1308694 | AE29: 462698 | AF29: 338265
A31: % use in IIS | B31: UPSBFG | E31: =IFERROR(E54/E26, "") | F31: =IFERROR(F54/F26, "") -> 1 | G31: =IFERROR(G54/G26, "") | H31: =IFERROR(H54/H26, "") -> 1 | I31: =IFERROR(I54/I26, "") -> 0.045991115 | J31: =IFERROR(J54/J26, "") -> 0.55496325 | K31: =IFERROR(K54/K26, "") -> 1 | L31: =IFERROR(L54/L26, "") | ... AF31: =IFERROR(AF54/AF26, "") -> 0.60527222
A32: % use in IIS | B32: UPSCOG | E32: =IFERROR(E59/E28, "") | F32: =IFERROR(F59/F28, "") | G32: =IFERROR(G59/G28, "") | H32: =IFERROR(H59/H28, "") -> 1 | I32: =IFERROR(I59/I28, "") -> 0.037074189 | J32: =IFERROR(J59/J28, "") -> 0 | K32: =IFERROR(K59/K28, "") | L32: =IFERROR(L59/L28, "") | ... AF32: =IFERROR(AF59/AF28, "") -> 0.0035473166
A35: ** Coking coal is a traded commodity; table below highlights net balance (consumption) based on domestic production + imports - exports
A37: Imports / Exports
A38: Subsector | B38: Primary energy commoditiy | D38: Unit | E38: AFE | F38: AFN | G38: AFW | H38: AFZ | I38: ANZ | J38: ASC | K38: ASE | L38: ASO | M38: BRA | N38: CAN | O38: CHL | P38: CHN | Q38: ENE | R38: ENW | S38: EUE | T38: EUM | U38: EUW | V38: IDN | W38: IND | X38: JPN | Y38: LAM | Z38: MDA | AA38: MEA | AB38: MEX | AC38: NIG | AD38: RUS | AE38: SKT | AF38: USA
A39: Import | B39: UPSCOK | D39: TJ | E39: 533 | F39: 11985 | G39: 0 | H39: 1925 | I39: 12117 | J39: 36538 | K39: 3653 | L39: 0 | M39: 37758 | N39: 18072 | O39: 29 | P39: 14803 | Q39: 48311 | R39: 36890 | S39: 57068 | T39: 58550 | U39: 133223 | V39: 48026 | W39: 81075 | X39: 20631 | Y39: 3585 | Z39: 19378 | AA39: 12319 | AB39: 33220 | AC39: 0 | AD39: 1913 | AE39: 8807 | AF39: 3031
A40: Export | B40: UPSCOK | D40: TJ | E40: 0 | F40: -4565 | G40: 0 | H40: -3022 | I40: -17739 | J40: -2818 | K40: 0 | L40: 0 | M40: 0 | N40: -3328 | O40: -1563 | P40: -185204 | Q40: -12439 | R40: -118 | S40: -216091 | T40: -12369 | U40: -58387 | V40: 0 | W40: -620 | X40: -46554 | Y40: -63257 | Z40: -3947 | AA40: -10180 | AB40: 0 | AC40: 0 | AD40: -81184 | AE40: 0 | AF40: -25343
A42: Regional use | B42: UPSCOK | D42: TJ | E42: =E29+E39+E40 -> 533 | F42: =F29+F39+F40 -> 20542 | G42: =G29+G39+G40 -> 0 | H42: =H29+H39+H40 -> 54126 | I42: =I29+I39+I40 -> 73640 | J42: =J29+J39+J40 -> 101038 | K42: =K29+K39+K40 -> 3653 | L42: =L29+L39+L40 -> 0 | ... AF42: =AF29+AF39+AF40 -> 315953
A43: % use in IIS | B43: UPSCOK | E43: =IFERROR(E60/E42, "") -> 0 | F43: =IFERROR(F60/F42, "") -> 0.21477948 | G43: =IFERROR(G60/G42, "") | H43: =IFERROR(H60/H42, "") -> 0.10748993 | I43: =IFERROR(I60/I42, "") -> 0.1661597 | J43: =IFERROR(J60/J42, "") -> 0.26640472 | K43: =IFERROR(K60/K42, "") -> 0.056118259 | L43: =IFERROR(L60/L42, "") | ... AF43: =IFERROR(AF60/AF42, "") -> 0.23380376
A47: ** The next section considers combining steel sector energy balances with production levels (see 'SteelProduction'), to estimate intensity of production values for each of the three production pathways
A49: ENERGY BALANCE - IIS
A50: Source: UN energy balances - Omnia_Energy_Balance_NEW_29_4_2024.xlsx
A52: Final Energy Use
A53: Subsector | B53: Subsector extended | C53: Primary energy commoditiy | D53: Unit | E53: AFE | F53: AFN | G53: AFW | H53: AFZ | I53: ANZ | J53: ASC | K53: ASE | L53: ASO | M53: BRA | N53: CAN | O53: CHL | P53: CHN | Q53: ENE | R53: ENW | S53: EUE | T53: EUM | U53: EUW | V53: IDN | W53: IND | X53: JPN | Y53: LAM | Z53: MDA | AA53: MEA | AB53: MEX | AC53: NIG | AD53: RUS | AE53: SKT | AF53: USA
A54: IIS | B54: Iron and steel | C54: INDBFG | D54: TJ | E54: =EnergyBalance!E38 -> 0 | F54: =EnergyBalance!F38 -> 3350 | G54: =EnergyBalance!G38 -> 0 | H54: =EnergyBalance!H38 -> 18142 | I54: =EnergyBalance!I38 -> 1087 | J54: =EnergyBalance!J38 -> 9890 | K54: =EnergyBalance!K38 -> 2654 | L54: =EnergyBalance!L38 -> 0 | ... AF54: =EnergyBalance!AF38 -> 66793
A55: IIS | B55: Iron and steel | C55: INDBGS | D55: TJ | E55: =EnergyBalance!E39 -> 0 | F55: =EnergyBalance!F39 -> 0 | G55: =EnergyBalance!G39 -> 0 | H55: =EnergyBalance!H39 -> 0 | I55: =EnergyBalance!I39 -> 0 | J55: =EnergyBalance!J39 -> 0 | K55: =EnergyBalance!K39 -> 0 | L55: =EnergyBalance!L39 -> 0 | ... AF55: =EnergyBalance!AF39 -> 0
A56: IIS | B56: Iron and steel | C56: INDBIO | D56: TJ | E56: =EnergyBalance!E40 -> 0 | F56: =EnergyBalance!F40 -> 0 | G56: =EnergyBalance!G40 -> 0 | H56: =EnergyBalance!H40 -> 0 | I56: =EnergyBalance!I40 -> 0 | J56: =EnergyBalance!J40 -> 0 | K56: =EnergyBalance!K40 -> 0 | L56: =EnergyBalance!L40 -> 0 | ... AF56: =EnergyBalance!AF40 -> 0
A57: IIS | B57: Iron and steel | C57: INDBLQ | D57: TJ | E57: =EnergyBalance!E41 -> 0 | F57: =EnergyBalance!F41 -> 0 | G57: =EnergyBalance!G41 -> 0 | H57: =EnergyBalance!H41 -> 0 | I57: =EnergyBalance!I41 -> 0 | J57: =EnergyBalance!J41 -> 0 | K57: =EnergyBalance!K41 -> 0 | L57: =EnergyBalance!L41 -> 0 | ... AF57: =EnergyBalance!AF41 -> 74
...

Sheet IIS_BY Techs
A1: Characterization of sectoral technologies
A2: Sector: | B2: Iron and Steel
A3: Code: | B3: IS
A5: Production pathways | H5: https://www.ipcc-nggip.iges.or.jp/public/2019rf/pdf/3_Volume3/19R_V3_Ch04_Metal_Industry.pdf | AM5: Process definition
A6: ~FI_T | AM6: ~FI_Process
A7: TechName | B7: *Technology Description | C7: Comm-OUT | D7: PRC_CAPACT | E7: NCAP_AFA | F7: FIXOM | G7: *NCAP_TLIFE | H7: Attribute | I7: *Unit | J7: AFE | K7: AFN | L7: AFW | M7: AFZ | N7: ANZ | O7: ASC | P7: ASE | Q7: ASO | R7: BRA | S7: CAN | T7: CHL | U7: CHN | V7: ENE | W7: ENW | X7: EUE | Y7: EUM | Z7: EUW | AA7: IDN | AB7: IND | AC7: JPN | AD7: LAM | AE7: MDA | AF7: MEA | AG7: MEX | AH7: NIG | AI7: RUS | AJ7: SKT | AK7: USA | AM7: Sets | AN7: TechName | AO7: TechDesc | AP7: Tact | AQ7: Tcap | AR7: *Comm-IN | AS7: Tslvl | AT7: PrimaryCG | AU7: Vintage
A8: *Technology Name | B8: Description | C8: Output Commodity | D8: Capacity to Activity Factor | E8: Availability factor | F8: Fixed costs ($M/Mt) | G8: Technical life | H8: TIMES attribute for regionalized variables -> | I8: unit | AM8: \I: Process Set Membership | AN8: Technology name | AO8: Description | AP8: Activity unit | AQ8: Capacity unit | AR8: Input Commodity | AS8: TimeSlice level of Process Activity | AT8: Primary Commodity Group | AU8: Vintage Tracking
A9: =AN9 -> I-IS-BF_BOF | B9: =AO9 -> IND Iron and Steel technology: BF-BOF | C9: IIS | D9: 1 | E9: ='Inputs_BY IIS'!AM$82 -> 0.8 | H9: PRC_RESID | I9: Mt | J9: ='Inputs_BY IIS'!E85*'Inputs_BY IIS'!E$81*'Inputs_BY IIS'!E$82 -> 0 | K9: ='Inputs_BY IIS'!F85*'Inputs_BY IIS'!F$81*'Inputs_BY IIS'!F$82 -> 1.2212887 | L9: ='Inputs_BY IIS'!G85*'Inputs_BY IIS'!G$81*'Inputs_BY IIS'!G$82 -> 0 | M9: ='Inputs_BY IIS'!H85*'Inputs_BY IIS'!H$81*'Inputs_BY IIS'!H$82 -> 6.0496933 | N9: ='Inputs_BY IIS'!I85*'Inputs_BY IIS'!I$81*'Inputs_BY IIS'!I$82 -> 5.4031611 | O9: ='Inputs_BY IIS'!J85*'Inputs_BY IIS'!J$81*'Inputs_BY IIS'!J$82 -> 4.3577082 | P9: ='Inputs_BY IIS'!K85*'Inputs_BY IIS'!K$81*'Inputs_BY IIS'!K$82 -> 1.0141361 | Q9: ='Inputs_BY IIS'!L85*'Inputs_BY IIS'!L$81*'Inputs_BY IIS'!L$82 -> 0 | ... AK9: ='Inputs_BY IIS'!AF85*'Inputs_BY IIS'!AF$81*'Inputs_BY IIS'!AF$82 -> 35.750563 | AM9: DMD | AN9: I-IS-BF_BOF | AO9: IND Iron and Steel technology: BF-BOF | AP9: PJ | AQ9: Mt
A10: =AN10 -> I-IS-DRI_EAF_COA | B10: =AO10 -> IND Iron and Steel technology: DRI using coal plus EAF | C10: IIS | D10: 1 | E10: ='Inputs_BY IIS'!AM$82 -> 0.8 | H10: PRC_RESID | I10: Mt | J10: ='Inputs_BY IIS'!E86*'Inputs_BY IIS'!E$81*(1-'Inputs_BY IIS'!E$130)/$E10 -> 0 | K10: ='Inputs_BY IIS'!F86*'Inputs_BY IIS'!F$81*(1-'Inputs_BY IIS'!F$130)/$E10 -> 0 | L10: ='Inputs_BY IIS'!G86*'Inputs_BY IIS'!G$81*(1-'Inputs_BY IIS'!G$130)/$E10 -> 0 | M10: ='Inputs_BY IIS'!H86*'Inputs_BY IIS'!H$81*(1-'Inputs_BY IIS'!H$130)/$E10 -> 0 | N10: ='Inputs_BY IIS'!I86*'Inputs_BY IIS'!I$81*(1-'Inputs_BY IIS'!I$130)/$E10 -> 0 | O10: ='Inputs_BY IIS'!J86*'Inputs_BY IIS'!J$81*(1-'Inputs_BY IIS'!J$130)/$E10 -> 0 | P10: ='Inputs_BY IIS'!K86*'Inputs_BY IIS'!K$81*(1-'Inputs_BY IIS'!K$130)/$E10 -> 0 | Q10: ='Inputs_BY IIS'!L86*'Inputs_BY IIS'!L$81*(1-'Inputs_BY IIS'!L$130)/$E10 -> 0 | ... AK10: ='Inputs_BY IIS'!AF86*'Inputs_BY IIS'!AF$81*(1-'Inputs_BY IIS'!AF$130)/$E10 -> 0 | AM10: DMD | AN10: I-IS-DRI_EAF_COA | AO10: IND Iron and Steel technology: DRI using coal plus EAF | AP10: PJ | AQ10: Mt
A11: =AN11 -> I-IS-DRI_EAF_NGA | B11: =AO11 -> IND Iron and Steel technology: DRI using gas plus EAF | C11: IIS | D11: 1 | E11: ='Inputs_BY IIS'!AM$82 -> 0.8 | H11: PRC_RESID | I11: Mt | J11: ='Inputs_BY IIS'!E86*'Inputs_BY IIS'!E$81*'Inputs_BY IIS'!E$130/$E11 -> 0.0068965223 | K11: ='Inputs_BY IIS'!F86*'Inputs_BY IIS'!F$81*'Inputs_BY IIS'!F$130/$E11 -> 2.5163449 | L11: ='Inputs_BY IIS'!G86*'Inputs_BY IIS'!G$81*'Inputs_BY IIS'!G$130/$E11 -> 0.0075861746 | M11: ='Inputs_BY IIS'!H86*'Inputs_BY IIS'!H$81*'Inputs_BY IIS'!H$130/$E11 -> 0.38923972 | N11: ='Inputs_BY IIS'!I86*'Inputs_BY IIS'!I$81*'Inputs_BY IIS'!I$130/$E11 -> 0.17413708 | O11: ='Inputs_BY IIS'!J86*'Inputs_BY IIS'!J$81*'Inputs_BY IIS'!J$130/$E11 -> 0.0578604 | P11: ='Inputs_BY IIS'!K86*'Inputs_BY IIS'!K$81*'Inputs_BY IIS'!K$130/$E11 -> 0.67609072 | Q11: ='Inputs_BY IIS'!L86*'Inputs_BY IIS'!L$81*'Inputs_BY IIS'!L$130/$E11 -> 0.42449661 | ... AK11: ='Inputs_BY IIS'!AF86*'Inputs_BY IIS'!AF$81*'Inputs_BY IIS'!AF$130/$E11 -> 7.2597497 | AM11: DMD | AN11: I-IS-DRI_EAF_NGA | AO11: IND Iron and Steel technology: DRI using gas plus EAF | AP11: PJ | AQ11: Mt
A12: =AN12 -> I-IS-SCP_EAF | B12: =AO12 -> IND Iron and Steel technology: EAF using scrap (secondary) | C12: IIS | D12: 1 | E12: ='Inputs_BY IIS'!AM$82 -> 0.8 | H12: PRC_RESID | I12: Mt | J12: ='Inputs_BY IIS'!E87*'Inputs_BY IIS'!E$81/$E12 -> 0.061936948 | K12: ='Inputs_BY IIS'!F87*'Inputs_BY IIS'!F$81/$E12 -> 2.2328419 | L12: ='Inputs_BY IIS'!G87*'Inputs_BY IIS'!G$81/$E12 -> 0.068130643 | M12: ='Inputs_BY IIS'!H87*'Inputs_BY IIS'!H$81/$E12 -> 3.4957214 | N12: ='Inputs_BY IIS'!I87*'Inputs_BY IIS'!I$81/$E12 -> 1.5840386 | O12: ='Inputs_BY IIS'!J87*'Inputs_BY IIS'!J$81/$E12 -> 0.5225153 | P12: ='Inputs_BY IIS'!K87*'Inputs_BY IIS'!K$81/$E12 -> 5.0706804 | Q12: ='Inputs_BY IIS'!L87*'Inputs_BY IIS'!L$81/$E12 -> 3.8334677 | ... AK12: ='Inputs_BY IIS'!AF87*'Inputs_BY IIS'!AF$81/$E12 -> 65.38047 | AM12: DMD | AN12: I-IS-SCP_EAF | AO12: IND Iron and Steel technology: EAF using scrap (secondary) | AP12: PJ | AQ12: Mt
A13: =AN9 -> I-IS-BF_BOF | B13: =AO9 -> IND Iron and Steel technology: BF-BOF | H13: NCAP_TLIFE | I13: Years | J13: 25 | K13: 25 | L13: 25 | M13: 25 | N13: 25 | O13: 25 | P13: 25 | Q13: 25 | R13: 25 | S13: 25 | T13: 25 | U13: 25 | V13: 25 | W13: 25 | X13: 25 | Y13: 25 | Z13: 25 | AA13: 25 | AB13: 25 | AC13: 25 | AD13: 25 | AE13: 25 | AF13: 25 | AG13: 25 | AH13: 25 | AI13: 25 | AJ13: 25 | AK13: 25 | AM13: MAT | AN13: I-IS-SCP_PRD | AO13: IND Scrap IS Dummy | AP13: Mt | AQ13: Mta
A14: =AN10 -> I-IS-DRI_EAF_COA | B14: =AO10 -> IND Iron and Steel technology: DRI using coal plus EAF | H14: NCAP_TLIFE | I14: Years | J14: 25 | K14: 25 | L14: 25 | M14: 25 | N14: 25 | O14: 25 | P14: 25 | Q14: 25 | R14: 25 | S14: 25 | T14: 25 | U14: 25 | V14: 25 | W14: 25 | X14: 25 | Y14: 25 | Z14: 25 | AA14: 25 | AB14: 25 | AC14: 25 | AD14: 25 | AE14: 25 | AF14: 25 | AG14: 25 | AH14: 25 | AI14: 25 | AJ14: 25 | AK14: 25
A15: =AN11 -> I-IS-DRI_EAF_NGA | B15: =AO11 -> IND Iron and Steel technology: DRI using gas plus EAF | H15: NCAP_TLIFE | I15: Years | J15: 25 | K15: 25 | L15: 25 | M15: 25 | N15: 25 | O15: 25 | P15: 25 | Q15: 25 | R15: 25 | S15: 25 | T15: 25 | U15: 25 | V15: 25 | W15: 25 | X15: 25 | Y15: 25 | Z15: 25 | AA15: 25 | AB15: 25 | AC15: 25 | AD15: 25 | AE15: 25 | AF15: 25 | AG15: 25 | AH15: 25 | AI15: 25 | AJ15: 25 | AK15: 25
A16: =AN12 -> I-IS-SCP_EAF | B16: =AO12 -> IND Iron and Steel technology: EAF using scrap (secondary) | H16: NCAP_TLIFE | I16: Years | J16: 25 | K16: 25 | L16: 25 | M16: 25 | N16: 25 | O16: 25 | P16: 25 | Q16: 25 | R16: 25 | S16: 25 | T16: 25 | U16: 25 | V16: 25 | W16: 25 | X16: 25 | Y16: 25 | Z16: 25 | AA16: 25 | AB16: 25 | AC16: 25 | AD16: 25 | AE16: 25 | AF16: 25 | AG16: 25 | AH16: 25 | AI16: 25 | AJ16: 25 | AK16: 25
A20: ~FI_T
A21: TechName | B21: *Technology Description | C21: Comm-IN | D21: Comm-OUT | E21: * | F21: * | G21: LimType | H21: Attribute | I21: *Unit | J21: AFE | K21: AFN | L21: AFW | M21: AFZ | N21: ANZ | O21: ASC | P21: ASE | Q21: ASO | R21: BRA | S21: CAN | T21: CHL | U21: CHN | V21: ENE | W21: ENW | X21: EUE | Y21: EUM | Z21: EUW | AA21: IDN | AB21: IND | AC21: JPN | AD21: LAM | AE21: MDA | AF21: MEA | AG21: MEX | AH21: NIG | AI21: RUS | AJ21: SKT | AK21: USA
A22: *Technology Name | B22: Description | C22: Input Commodity | D22: Output commodity | G22: Sign of the equation | H22: TIMES attribute for regionalized variables -> | I22: unit
A23: =AN9 -> I-IS-BF_BOF | B23: =AO9 -> IND Iron and Steel technology: BF-BOF | C23: INDBGS | H23: INPUT | I23: PJ / Mt | J23: ='Inputs_BY IIS'!E258 | K23: ='Inputs_BY IIS'!F258 | L23: ='Inputs_BY IIS'!G258 | M23: ='Inputs_BY IIS'!H258 | N23: ='Inputs_BY IIS'!I258 | O23: ='Inputs_BY IIS'!J258 | P23: ='Inputs_BY IIS'!K258 | Q23: ='Inputs_BY IIS'!L258 | ... AK23: ='Inputs_BY IIS'!AF258
C24: INDBIO | H24: INPUT | I24: PJ / Mt | J24: ='Inputs_BY IIS'!E259 | K24: ='Inputs_BY IIS'!F259 | L24: ='Inputs_BY IIS'!G259 | M24: ='Inputs_BY IIS'!H259 | N24: ='Inputs_BY IIS'!I259 | O24: ='Inputs_BY IIS'!J259 | P24: ='Inputs_BY IIS'!K259 | Q24: ='Inputs_BY IIS'!L259 | ... AK24: ='Inputs_BY IIS'!AF259
C25: INDBLQ | H25: INPUT | I25: PJ / Mt | J25: ='Inputs_BY IIS'!E260 | K25: ='Inputs_BY IIS'!F260 | L25: ='Inputs_BY IIS'!G260 | M25: ='Inputs_BY IIS'!H260 | N25: ='Inputs_BY IIS'!I260 | O25: ='Inputs_BY IIS'!J260 | P25: ='Inputs_BY IIS'!K260 | Q25: ='Inputs_BY IIS'!L260 | ... AK25: ='Inputs_BY IIS'!AF260 -> 0.0025873719
C26: INDCOA | H26: INPUT | I26: PJ / Mt | J26: ='Inputs_BY IIS'!E261 | K26: ='Inputs_BY IIS'!F261 -> 0.012282108 | L26: ='Inputs_BY IIS'!G261 | M26: ='Inputs_BY IIS'!H261 -> 6.7475262 | N26: ='Inputs_BY IIS'!I261 -> 0.14320321 | O26: ='Inputs_BY IIS'!J261 -> 6.7475262 | P26: ='Inputs_BY IIS'!K261 -> 3.4684694 | Q26: ='Inputs_BY IIS'!L261 | ... AK26: ='Inputs_BY IIS'!AF261 -> 0.30985526
C27: INDCOG | H27: INPUT | I27: PJ / Mt | J27: ='Inputs_BY IIS'!E262 | K27: ='Inputs_BY IIS'!F262 | L27: ='Inputs_BY IIS'!G262 | M27: ='Inputs_BY IIS'!H262 -> 2.4724841 | N27: ='Inputs_BY IIS'!I262 -> 0.21376375 | O27: ='Inputs_BY IIS'!J262 | P27: ='Inputs_BY IIS'!K262 | Q27: ='Inputs_BY IIS'!L262 | ... AK27: ='Inputs_BY IIS'!AF262 -> 0.0075872932
C28: INDCOK | H28: INPUT | I28: PJ / Mt | J28: ='Inputs_BY IIS'!E263 | K28: ='Inputs_BY IIS'!F263 -> 4.5157218 | L28: ='Inputs_BY IIS'!G263 | M28: ='Inputs_BY IIS'!H263 -> 1.2021271 | N28: ='Inputs_BY IIS'!I263 -> 2.8307503 | O28: ='Inputs_BY IIS'!J263 -> 7.7210884 | P28: ='Inputs_BY IIS'!K263 -> 0.25267812 | Q28: ='Inputs_BY IIS'!L263 | ... AK28: ='Inputs_BY IIS'!AF263 -> 2.5828614
C29: INDELC | H29: INPUT | I29: PJ / Mt | J29: ='Inputs_BY IIS'!E264 | K29: ='Inputs_BY IIS'!F264 | L29: ='Inputs_BY IIS'!G264 | M29: ='Inputs_BY IIS'!H264 -> 12.904221 | N29: ='Inputs_BY IIS'!I264 -> 3.2928096 | O29: ='Inputs_BY IIS'!J264 -> 15.280454 | P29: ='Inputs_BY IIS'!K264 -> 15.280454 | Q29: ='Inputs_BY IIS'!L264 | ... AK29: ='Inputs_BY IIS'!AF264 -> 2.8803194
C30: INDGAS | H30: INPUT | I30: PJ / Mt | J30: ='Inputs_BY IIS'!E265 | K30: ='Inputs_BY IIS'!F265 -> 10.492673 | L30: ='Inputs_BY IIS'!G265 | M30: ='Inputs_BY IIS'!H265 -> 0.93581673 | N30: ='Inputs_BY IIS'!I265 -> 1.465428 | O30: ='Inputs_BY IIS'!J265 -> 7.0368627 | P30: ='Inputs_BY IIS'!K265 -> 8.3961998 | Q30: ='Inputs_BY IIS'!L265 | ... AK30: ='Inputs_BY IIS'!AF265 -> 10.492673
C31: INDHET | H31: INPUT | I31: PJ / Mt | J31: ='Inputs_BY IIS'!E266 | K31: ='Inputs_BY IIS'!F266 | L31: ='Inputs_BY IIS'!G266 | M31: ='Inputs_BY IIS'!H266 | N31: ='Inputs_BY IIS'!I266 | O31: ='Inputs_BY IIS'!J266 -> 4.8418281 | P31: ='Inputs_BY IIS'!K266 | Q31: ='Inputs_BY IIS'!L266 | ... AK31: ='Inputs_BY IIS'!AF266 -> 0.25618478
C32: INDLPG | H32: INPUT | I32: PJ / Mt | J32: ='Inputs_BY IIS'!E267 | K32: ='Inputs_BY IIS'!F267 | L32: ='Inputs_BY IIS'!G267 | M32: ='Inputs_BY IIS'!H267 | N32: ='Inputs_BY IIS'!I267 -> 0.0069403816 | O32: ='Inputs_BY IIS'!J267 -> 0.44454892 | P32: ='Inputs_BY IIS'!K267 -> 0.44454892 | Q32: ='Inputs_BY IIS'!L267 | ... AK32: ='Inputs_BY IIS'!AF267 -> 0.0031817681
C33: INDOIL | H33: INPUT | I33: PJ / Mt | J33: ='Inputs_BY IIS'!E268 | K33: ='Inputs_BY IIS'!F268 -> 2.1005555 | L33: ='Inputs_BY IIS'!G268 | M33: ='Inputs_BY IIS'!H268 -> 0.10455075 | N33: ='Inputs_BY IIS'!I268 -> 0.19456203 | O33: ='Inputs_BY IIS'!J268 -> 2.1005555 | P33: ='Inputs_BY IIS'!K268 -> 2.1005555 | Q33: ='Inputs_BY IIS'!L268 | ... AK33: ='Inputs_BY IIS'!AF268 -> 0.1270959
C34: INDWAS | H34: INPUT | I34: PJ / Mt | J34: ='Inputs_BY IIS'!E271 | K34: ='Inputs_BY IIS'!F271 | L34: ='Inputs_BY IIS'!G271 | M34: ='Inputs_BY IIS'!H271 | N34: ='Inputs_BY IIS'!I271 | O34: ='Inputs_BY IIS'!J271 | P34: ='Inputs_BY IIS'!K271 | Q34: ='Inputs_BY IIS'!L271 | ... AK34: ='Inputs_BY IIS'!AF271
C35: BIOMASS | H35: INPUT | I35: PJ / Mt | J35: ='Inputs_BY IIS'!E193 | K35: ='Inputs_BY IIS'!F193 | L35: ='Inputs_BY IIS'!G193 | M35: ='Inputs_BY IIS'!H193 | N35: ='Inputs_BY IIS'!I193 | O35: ='Inputs_BY IIS'!J193 | P35: ='Inputs_BY IIS'!K193 | Q35: ='Inputs_BY IIS'!L193 | ... AK35: ='Inputs_BY IIS'!AF193 | AN35: [UPS denotes input into BF; however technology combines both BF and BOF]
C36: COA | H36: INPUT | I36: PJ / Mt | J36: ='Inputs_BY IIS'!E194 | K36: =IF('Inputs_BY IIS'!F194=0,"",'Inputs_BY IIS'!F194) -> 0.51994258 | L36: =IF('Inputs_BY IIS'!G194=0,"",'Inputs_BY IIS'!G194) | M36: =IF('Inputs_BY IIS'!H194=0,"",'Inputs_BY IIS'!H194) | N36: =IF('Inputs_BY IIS'!I194=0,"",'Inputs_BY IIS'!I194) -> 0.37987022 | O36: =IF('Inputs_BY IIS'!J194=0,"",'Inputs_BY IIS'!J194) | P36: =IF('Inputs_BY IIS'!K194=0,"",'Inputs_BY IIS'!K194) | Q36: =IF('Inputs_BY IIS'!L194=0,"",'Inputs_BY IIS'!L194) | R36: =IF('Inputs_BY IIS'!M194=0,"",'Inputs_BY IIS'!M194) | ... AK36: =IF('Inputs_BY IIS'!AF194=0,"",'Inputs_BY IIS'!AF194) -> 0.93907613
C37: COACOK | H37: INPUT | I37: PJ / Mt | J37: ='Inputs_BY IIS'!E195 | K37: =IF('Inputs_BY IIS'!F195=0,"",'Inputs_BY IIS'!F195) -> 15.425621 | L37: =IF('Inputs_BY IIS'!G195=0,"",'Inputs_BY IIS'!G195) | M37: =IF('Inputs_BY IIS'!H195=0,"",'Inputs_BY IIS'!H195) -> 9.3659707 | N37: =IF('Inputs_BY IIS'!I195=0,"",'Inputs_BY IIS'!I195) -> 12.216691 | O37: =IF('Inputs_BY IIS'!J195=0,"",'Inputs_BY IIS'!J195) -> 15.425621 | P37: =IF('Inputs_BY IIS'!K195=0,"",'Inputs_BY IIS'!K195) -> 5.9878552 | Q37: =IF('Inputs_BY IIS'!L195=0,"",'Inputs_BY IIS'!L195) | R37: =IF('Inputs_BY IIS'!M195=0,"",'Inputs_BY IIS'!M195) | ... AK37: =IF('Inputs_BY IIS'!AF195=0,"",'Inputs_BY IIS'!AF195) -> 8.3854974
C38: GASNAT | H38: INPUT | I38: PJ / Mt | J38: ='Inputs_BY IIS'!E196 | K38: ='Inputs_BY IIS'!F196 | L38: ='Inputs_BY IIS'!G196 | M38: ='Inputs_BY IIS'!H196 | N38: ='Inputs_BY IIS'!I196 | O38: ='Inputs_BY IIS'!J196 | P38: ='Inputs_BY IIS'!K196 | Q38: ='Inputs_BY IIS'!L196 | ... AK38: ='Inputs_BY IIS'!AF196
C39: OILHFO | H39: INPUT | I39: PJ / Mt | J39: ='Inputs_BY IIS'!E197 | K39: ='Inputs_BY IIS'!F197 | L39: ='Inputs_BY IIS'!G197 | M39: ='Inputs_BY IIS'!H197 | N39: ='Inputs_BY IIS'!I197 | O39: ='Inputs_BY IIS'!J197 -> 1.3127 | P39: ='Inputs_BY IIS'!K197 | Q39: ='Inputs_BY IIS'!L197 | ... AK39: ='Inputs_BY IIS'!AF197
C40: OILOPP | H40: INPUT | I40: PJ / Mt | J40: ='Inputs_BY IIS'!E198 | K40: ='Inputs_BY IIS'!F198 | L40: ='Inputs_BY IIS'!G198 | M40: ='Inputs_BY IIS'!H198 | N40: ='Inputs_BY IIS'!I198 | O40: ='Inputs_BY IIS'!J198 | P40: ='Inputs_BY IIS'!K198 | Q40: ='Inputs_BY IIS'!L198 | ... AK40: ='Inputs_BY IIS'!AF198
C41: IISSCP | H41: INPUT | I41: Mt / Mt | K41: ='Inputs_BY IIS'!F89 -> 0.125 | M41: ='Inputs_BY IIS'!H89 -> 0.125 | N41: ='Inputs_BY IIS'!I89 -> 0.125 | O41: ='Inputs_BY IIS'!J89 -> 0.125 | P41: ='Inputs_BY IIS'!K89 -> 0.125 | R41: ='Inputs_BY IIS'!M89 -> 0.125 | S41: ='Inputs_BY IIS'!N89 -> 0.125 | T41: ='Inputs_BY IIS'!O89 -> 0.125 | U41: ='Inputs_BY IIS'!P89 -> 0.125 | V41: ='Inputs_BY IIS'!Q89 -> 0.125 | W41: ='Inputs_BY IIS'!R89 -> 0.125 | X41: ='Inputs_BY IIS'!S89 -> 0.125 | Y41: ='Inputs_BY IIS'!T89 -> 0.125 | ... AG41: ='Inputs_BY IIS'!AB89 -> 0.125 | AI41: ='Inputs_BY IIS'!AD89 -> 0.125 | AJ41: ='Inputs_BY IIS'!AE89 -> 0.125 | AK41: ='Inputs_BY IIS'!AF89 -> 0.125
D42: GASBFG | H42: OUTPUT | I42: PJ / Mt | J42: =IF('Inputs_BY IIS'!E176=0,"",'Inputs_BY IIS'!E176) | K42: =IF('Inputs_BY IIS'!F176=0,"",'Inputs_BY IIS'!F176) | L42: =IF('Inputs_BY IIS'!G176=0,"",'Inputs_BY IIS'!G176) | M42: =IF('Inputs_BY IIS'!H176=0,"",'Inputs_BY IIS'!H176) | N42: =IF('Inputs_BY IIS'!I176=0,"",'Inputs_BY IIS'!I176) -> 5.2163908 | O42: =IF('Inputs_BY IIS'!J176=0,"",'Inputs_BY IIS'!J176) -> 2.2749917 | P42: =IF('Inputs_BY IIS'!K176=0,"",'Inputs_BY IIS'!K176) | Q42: =IF('Inputs_BY IIS'!L176=0,"",'Inputs_BY IIS'!L176) | ... AK42: =IF('Inputs_BY IIS'!AF176=0,"",'Inputs_BY IIS'!AF176) -> 1.523018 | AN42: ='Inputs_BY IIS'!AH176 -> BFG production net of use in I&S sector
D43: INDCO2c | H43: OUTPUT | I43: kt/Mt | J43: =IF(IFERROR($AM43*('Inputs_BY IIS'!E186+'Inputs_BY IIS'!E189),"")=0,"",IFERROR($AM43*('Inputs_BY IIS'!E186+'Inputs_BY IIS'!E189),"")) | K43: =IF(IFERROR($AM43*('Inputs_BY IIS'!F186+'Inputs_BY IIS'!F189),"")=0,"",IFERROR($AM43*('Inputs_BY IIS'!F186+'Inputs_BY IIS'!F189),"")) -> 891.47636 | L43: =IF(IFERROR($AM43*('Inputs_BY IIS'!G186+'Inputs_BY IIS'!G189),"")=0,"",IFERROR($AM43*('Inputs_BY IIS'!G186+'Inputs_BY IIS'!G189),"")) | M43: =IF(IFERROR($AM43*('Inputs_BY IIS'!H186+'Inputs_BY IIS'!H189),"")=0,"",IFERROR($AM43*('Inputs_BY IIS'!H186+'Inputs_BY IIS'!H189),"")) -> 974.61966 | N43: =IF(IFERROR($AM43*('Inputs_BY IIS'!I186+'Inputs_BY IIS'!I189),"")=0,"",IFERROR($AM43*('Inputs_BY IIS'!I186+'Inputs_BY IIS'!I189),"")) -> 1091.301 | O43: =IF(IFERROR($AM43*('Inputs_BY IIS'!J186+'Inputs_BY IIS'!J189),"")=0,"",IFERROR($AM43*('Inputs_BY IIS'!J186+'Inputs_BY IIS'!J189),"")) -> 1329.0243 | P43: =IF(IFERROR($AM43*('Inputs_BY IIS'!K186+'Inputs_BY IIS'!K189),"")=0,"",IFERROR($AM43*('Inputs_BY IIS'!K186+'Inputs_BY IIS'!K189),"")) -> 850.52688 | Q43: =IF(IFERROR($AM43*('Inputs_BY IIS'!L186+'Inputs_BY IIS'!L189),"")=0,"",IFERROR($AM43*('Inputs_BY IIS'!L186+'Inputs_BY IIS'!L189),"")) | ... AK43: =IF(IFERROR($AM43*('Inputs_BY IIS'!AF186+'Inputs_BY IIS'!AF189),"")=0,"",IFERROR($AM43*('Inputs_BY IIS'!AF186+'Inputs_BY IIS'!AF189),"")) -> 807.39638 | AM43: 260 | AN43: KtCO2/PJ for combustion of BFG (as a final energy commodity in the process)
D44: INDCO2p | H44: OUTPUT | I44: kt/Mt | J44: =IF('Inputs_BY IIS'!E81*'Inputs_BY IIS'!E85=0,"",$AM$44) | K44: =IF('Inputs_BY IIS'!F81*'Inputs_BY IIS'!F85=0,"",$AM$44) -> 392.37852 | L44: =IF('Inputs_BY IIS'!G81*'Inputs_BY IIS'!G85=0,"",$AM$44) | M44: =IF('Inputs_BY IIS'!H81*'Inputs_BY IIS'!H85=0,"",$AM$44) -> 392.37852 | N44: =IF('Inputs_BY IIS'!I81*'Inputs_BY IIS'!I85=0,"",$AM$44) -> 392.37852 | O44: =IF('Inputs_BY IIS'!J81*'Inputs_BY IIS'!J85=0,"",$AM$44) -> 392.37852 | P44: =IF('Inputs_BY IIS'!K81*'Inputs_BY IIS'!K85=0,"",$AM$44) -> 392.37852 | Q44: =IF('Inputs_BY IIS'!L81*'Inputs_BY IIS'!L85=0,"",$AM$44) | ... AK44: =IF('Inputs_BY IIS'!AF81*'Inputs_BY IIS'!AF85=0,"",$AM$44) -> 392.37852 | AM44: =523000/(SUM(J9:AK9)/1.25) -> 392.37852 | AN44: KtCO2/Mt of steel (calibration factor for iron and steel process emissions)
...

Sheet IIS_New Techs
A1: Characterization of new sectoral technology options
A2: Sector: | B2: Iron and steel
A3: Code: | B3: IS
A7: New Steel Production Processes | AK7: Process definition
A8: ~FI_T | AK8: ~FI_Process
A9: TechName | B9: *Technology Description | C9: *Comm-IN | D9: Comm-OUT | E9: PRC_CAPACT | F9: NCAP_AFA | G9: START | H9: NCAP_TLIFE | AK9: Sets | AL9: TechName | AM9: TechDesc | AN9: Tact | AO9: Tcap | AP9: *Comm-IN | AQ9: Tslvl | AR9: PrimaryCG | AS9: Vintage
A10: *Technology Name | B10: Description | C10: Input Commodity | D10: Output Commodity | E10: Capacity to Activity Factor | F10: Availability factor | G10: Start year | H10: Technical life | AK10: \I: Process Set Membership | AL10: Technology name | AM10: Description | AN10: Activity unit | AO10: Capacity unit | AP10: Input Commodity | AQ10: TimeSlice level of Process Activity | AR10: Primary Commodity Group | AS10: Vintage Tracking
A11: =AL11 -> I-IS-BF_BOF01 | B11: =AM11 -> IND Iron and Steel technology: BF-BOF | D11: IIS | E11: 1 | F11: 0.95 | G11: 2020 | H11: 30 | AK11: DMD | AL11: I-IS-BF_BOF01 | AM11: IND Iron and Steel technology: BF-BOF | AN11: Mt | AO11: Mt_a
A12: =AL12 -> I-IS-BF_BOF02 | B12: =AM12 -> IND Iron and Steel technology: BF-BOF - High bio | D12: IIS | E12: 1 | F12: 0.95 | G12: 2020 | H12: 30 | AK12: DMD | AL12: I-IS-BF_BOF02 | AM12: IND Iron and Steel technology: BF-BOF - High bio | AN12: Mt | AO12: Mt_a
A13: =AL13 -> I-IS-DRI_EAF_COA01 | B13: =AM13 -> IND Iron and Steel technology: DRI using coal plus EAF | D13: IIS | E13: 1 | F13: 0.95 | G13: 2020 | H13: 30 | AK13: DMD | AL13: I-IS-DRI_EAF_COA01 | AM13: IND Iron and Steel technology: DRI using coal plus EAF | AN13: Mt | AO13: Mt_a
A14: =AL14 -> I-IS-DRI_EAF_NGA01 | B14: =AM14 -> IND Iron and Steel technology: DRI using gas plus EAF | D14: IIS | E14: 1 | F14: 0.95 | G14: 2020 | H14: 30 | AK14: DMD | AL14: I-IS-DRI_EAF_NGA01 | AM14: IND Iron and Steel technology: DRI using gas plus EAF | AN14: Mt | AO14: Mt_a
A15: =AL15 -> I-IS-DRI_EAF_H201 | B15: =AM15 -> IND Iron and Steel technology: DRI using H2 plus EAF | D15: IIS | E15: 1 | F15: 0.95 | G15: 2020 | H15: 30 | AK15: DMD | AL15: I-IS-DRI_EAF_H201 | AM15: IND Iron and Steel technology: DRI using H2 plus EAF | AN15: Mt | AO15: Mt_a
A16: =AL16 -> I-IS-SCP_EAF01 | B16: =AM16 -> IND Iron and Steel technology: EAF using scrap (secondary) | D16: IIS | E16: 1 | F16: 0.95 | G16: 2020 | H16: 30 | AK16: DMD | AL16: I-IS-SCP_EAF01 | AM16: IND Iron and Steel technology: EAF using scrap (secondary) | AN16: Mt | AO16: Mt_a
A17: =AL17 -> I-IS-BF_BOF01_CCS | B17: =AM17 -> IND Iron and Steel technology: BF-BOF w/CCS | D17: IIS | E17: 1 | F17: 0.95 | G17: 2035 | H17: 30 | AK17: DMD | AL17: I-IS-BF_BOF01_CCS | AM17: IND Iron and Steel technology: BF-BOF w/CCS | AN17: Mt | AO17: Mt_a
A18: =AL18 -> I-IS-BF_BOF02_CCS | B18: =AM18 -> IND Iron and Steel technology: BF-BOF - High bio w/CCS | D18: IIS | E18: 1 | F18: 0.95 | G18: 2035 | H18: 30 | AK18: DMD | AL18: I-IS-BF_BOF02_CCS | AM18: IND Iron and Steel technology: BF-BOF - High bio w/CCS | AN18: Mt | AO18: Mt_a
A19: =AL19 -> I-IS-DRI_EAF_COA01_CCS | B19: =AM19 -> IND Iron and Steel technology: DRI using coal plus EAF w/CCS | D19: IIS | E19: 1 | F19: 0.95 | G19: 2035 | H19: 30 | AK19: DMD | AL19: I-IS-DRI_EAF_COA01_CCS | AM19: IND Iron and Steel technology: DRI using coal plus EAF w/CCS | AN19: Mt | AO19: Mt_a
A20: =AL20 -> I-IS-DRI_EAF_NGA01_CCS | B20: =AM20 -> IND Iron and Steel technology: DRI using gas plus EAF w/CCS | D20: IIS | E20: 1 | F20: 0.95 | G20: 2035 | H20: 30 | AK20: DMD | AL20: I-IS-DRI_EAF_NGA01_CCS | AM20: IND Iron and Steel technology: DRI using gas plus EAF w/CCS | AN20: Mt | AO20: Mt_a
A21: =AL21 -> I-IS-MOE01 | B21: =AM21 -> IND Iron and Steel technology: Molten Oxide Electrolysis | D21: IIS | E21: 1 | F21: 0.95 | G21: 2035 | H21: 30 | AK21: DMD | AL21: I-IS-MOE01 | AM21: IND Iron and Steel technology: Molten Oxide Electrolysis | AN21: Mt | AO21: Mt_a
A24: ~FI_T
A25: TechName | B25: *Technology Description | C25: Comm-IN | D25: Comm-OUT | E25: LimType | F25: Attribute | G25: *Unit | H25: AFE | I25: AFN | J25: AFW | K25: AFZ | L25: ANZ | M25: ASC | N25: ASE | O25: ASO | P25: BRA | Q25: CAN | R25: CHL | S25: CHN | T25: ENE | U25: ENW | V25: EUE | W25: EUM | X25: EUW | Y25: IDN | Z25: IND | AA25: JPN | AB25: LAM | AC25: MDA | AD25: MEA | AE25: MEX | AF25: NIG | AG25: RUS | AH25: SKT | AI25: USA
A26: *Technology Name | B26: Description | C26: Input Commodity | D26: Output commodity | E26: Sign of the equation | F26: TIMES attribute for regionalized variables -> | G26: unit
A27: =AL11 -> I-IS-BF_BOF01 | B27: =AM11 -> IND Iron and Steel technology: BF-BOF | C27: INDCOA | F27: INPUT | G27: PJ/Mt | H27: =$AK27 -> 1.5 | I27: =$AK27 -> 1.5 | J27: =$AK27 -> 1.5 | K27: =$AK27 -> 1.5 | L27: =$AK27 -> 1.5 | M27: =$AK27 -> 1.5 | N27: =$AK27 -> 1.5 | O27: =$AK27 -> 1.5 | ... AI27: =$AK27 -> 1.5 | AK27: 1.5
C28: INDCOG | F28: INPUT | G28: PJ/Mt | H28: =$AK28 -> 1 | I28: =$AK28 -> 1 | J28: =$AK28 -> 1 | K28: =$AK28 -> 1 | L28: =$AK28 -> 1 | M28: =$AK28 -> 1 | N28: =$AK28 -> 1 | O28: =$AK28 -> 1 | ... AI28: =$AK28 -> 1 | AK28: 1
C29: INDCOK | F29: INPUT | G29: PJ/Mt | H29: =$AK29 -> 1.5 | I29: =$AK29 -> 1.5 | J29: =$AK29 -> 1.5 | K29: =$AK29 -> 1.5 | L29: =$AK29 -> 1.5 | M29: =$AK29 -> 1.5 | N29: =$AK29 -> 1.5 | O29: =$AK29 -> 1.5 | ... AI29: =$AK29 -> 1.5 | AK29: 1.5
C30: INDELC | F30: INPUT | G30: PJ/Mt | H30: =$AK30 -> 1.5 | I30: =$AK30 -> 1.5 | J30: =$AK30 -> 1.5 | K30: =$AK30 -> 1.5 | L30: =$AK30 -> 1.5 | M30: =$AK30 -> 1.5 | N30: =$AK30 -> 1.5 | O30: =$AK30 -> 1.5 | ... AI30: =$AK30 -> 1.5 | AK30: 1.5
C31: INDGAS | F31: INPUT | G31: PJ/Mt | H31: =$AK31 -> 2 | I31: =$AK31 -> 2 | J31: =$AK31 -> 2 | K31: =$AK31 -> 2 | L31: =$AK31 -> 2 | M31: =$AK31 -> 2 | N31: =$AK31 -> 2 | O31: =$AK31 -> 2 | ... AI31: =$AK31 -> 2 | AK31: 2
C32: UPSCOA | F32: INPUT | G32: PJ/Mt | H32: =$AK32 -> 2 | I32: =$AK32 -> 2 | J32: =$AK32 -> 2 | K32: =$AK32 -> 2 | L32: =$AK32 -> 2 | M32: =$AK32 -> 2 | N32: =$AK32 -> 2 | O32: =$AK32 -> 2 | ... AI32: =$AK32 -> 2 | AK32: 2
C33: UPSCOK | F33: INPUT | G33: PJ/Mt | H33: =$AK33 -> 8 | I33: =$AK33 -> 8 | J33: =$AK33 -> 8 | K33: =$AK33 -> 8 | L33: =$AK33 -> 8 | M33: =$AK33 -> 8 | N33: =$AK33 -> 8 | O33: =$AK33 -> 8 | ... AI33: =$AK33 -> 8 | AK33: 8
D34: INDCO2p | F34: OUTPUT | G34: kt/Mt | H34: =$AL34*1000 -> 1580 | I34: =$AL34*1000 -> 1580 | J34: =$AL34*1000 -> 1580 | K34: =$AL34*1000 -> 1580 | L34: =$AL34*1000 -> 1580 | M34: =$AL34*1000 -> 1580 | N34: =$AL34*1000 -> 1580 | O34: =$AL34*1000 -> 1580 | ... AI34: =$AL34*1000 -> 1580 | AL34: =1.58 -> 1.58 | AM34: From IPCC, https://www.ipcc-nggip.iges.or.jp/public/2019rf/pdf/3_Volume3/19R_V3_Ch04_Metal_Industry.pdf
D35: GASBFG | F35: OUTPUT | G35: PJ / Mt | H35: =$AL$35 -> 1.2624923 | I35: =$AL$35 -> 1.2624923 | J35: =$AL$35 -> 1.2624923 | K35: =$AL$35 -> 1.2624923 | L35: =$AL$35 -> 1.2624923 | M35: =$AL$35 -> 1.2624923 | N35: =$AL$35 -> 1.2624923 | O35: =$AL$35 -> 1.2624923 | ... AI35: =$AL$35 -> 1.2624923 | AL35: ='IIS_BY Techs'!U42 -> 1.2624923 | AM35: Uses the value from CHN as the basis for BFG generation (note the wide variation in regional base year values)
C36: IISSCP | F36: INPUT | G36: Mt/Mt | H36: =$AK36 -> 0.125 | I36: =$AK36 -> 0.125 | J36: =$AK36 -> 0.125 | K36: =$AK36 -> 0.125 | L36: =$AK36 -> 0.125 | M36: =$AK36 -> 0.125 | N36: =$AK36 -> 0.125 | O36: =$AK36 -> 0.125 | ... AI36: =$AK36 -> 0.125 | AK36: 0.125
A37: =AL12 -> I-IS-BF_BOF02 | B37: =AM12 -> IND Iron and Steel technology: BF-BOF - High bio | C37: INDCOA | F37: INPUT | G37: PJ/Mt | H37: =$AK37 -> 1.1571429 | I37: =$AK37 -> 1.1571429 | J37: =$AK37 -> 1.1571429 | K37: =$AK37 -> 1.1571429 | L37: =$AK37 -> 1.1571429 | M37: =$AK37 -> 1.1571429 | N37: =$AK37 -> 1.1571429 | O37: =$AK37 -> 1.1571429 | ... AI37: =$AK37 -> 1.1571429 | AK37: =((SUM($AK$27:$AK$33)-$AK$42)/SUM($AK$27:$AK$33))*AK27 -> 1.1571429
C38: INDCOG | F38: INPUT | G38: PJ/Mt | H38: =$AK38 -> 0.77142857 | I38: =$AK38 -> 0.77142857 | J38: =$AK38 -> 0.77142857 | K38: =$AK38 -> 0.77142857 | L38: =$AK38 -> 0.77142857 | M38: =$AK38 -> 0.77142857 | N38: =$AK38 -> 0.77142857 | O38: =$AK38 -> 0.77142857 | ... AI38: =$AK38 -> 0.77142857 | AK38: =((SUM($AK$27:$AK$33)-$AK$42)/SUM($AK$27:$AK$33))*AK28 -> 0.77142857
C39: INDCOK | F39: INPUT | G39: PJ/Mt | H39: =$AK39 -> 1.1571429 | I39: =$AK39 -> 1.1571429 | J39: =$AK39 -> 1.1571429 | K39: =$AK39 -> 1.1571429 | L39: =$AK39 -> 1.1571429 | M39: =$AK39 -> 1.1571429 | N39: =$AK39 -> 1.1571429 | O39: =$AK39 -> 1.1571429 | ... AI39: =$AK39 -> 1.1571429 | AK39: =((SUM($AK$27:$AK$33)-$AK$42)/SUM($AK$27:$AK$33))*AK29 -> 1.1571429
C40: INDELC | F40: INPUT | G40: PJ/Mt | H40: =$AK40 -> 1.1571429 | I40: =$AK40 -> 1.1571429 | J40: =$AK40 -> 1.1571429 | K40: =$AK40 -> 1.1571429 | L40: =$AK40 -> 1.1571429 | M40: =$AK40 -> 1.1571429 | N40: =$AK40 -> 1.1571429 | O40: =$AK40 -> 1.1571429 | ... AI40: =$AK40 -> 1.1571429 | AK40: =((SUM($AK$27:$AK$33)-$AK$42)/SUM($AK$27:$AK$33))*AK30 -> 1.1571429
C41: INDGAS | F41: INPUT | G41: PJ/Mt | H41: =$AK41 -> 1.5428571 | I41: =$AK41 -> 1.5428571 | J41: =$AK41 -> 1.5428571 | K41: =$AK41 -> 1.5428571 | L41: =$AK41 -> 1.5428571 | M41: =$AK41 -> 1.5428571 | N41: =$AK41 -> 1.5428571 | O41: =$AK41 -> 1.5428571 | ... AI41: =$AK41 -> 1.5428571 | AK41: =((SUM($AK$27:$AK$33)-$AK$42)/SUM($AK$27:$AK$33))*AK31 -> 1.5428571
C42: INDBIO | F42: INPUT | G42: PJ/Mt | H42: =$AK42 -> 4 | I42: =$AK42 -> 4 | J42: =$AK42 -> 4 | K42: =$AK42 -> 4 | L42: =$AK42 -> 4 | M42: =$AK42 -> 4 | N42: =$AK42 -> 4 | O42: =$AK42 -> 4 | ... AI42: =$AK42 -> 4 | AK42: 4
C43: UPSCOA | F43: INPUT | G43: PJ/Mt | H43: =$AK43 -> 1.5428571 | I43: =$AK43 -> 1.5428571 | J43: =$AK43 -> 1.5428571 | K43: =$AK43 -> 1.5428571 | L43: =$AK43 -> 1.5428571 | M43: =$AK43 -> 1.5428571 | N43: =$AK43 -> 1.5428571 | O43: =$AK43 -> 1.5428571 | ... AI43: =$AK43 -> 1.5428571 | AK43: =((SUM($AK$27:$AK$33)-$AK$42)/SUM($AK$27:$AK$33))*AK32 -> 1.5428571
