Workbook

Sheet Data
A1: Source | B1: [Pietro - can you fill this in?]
A3: MISO2_country | B3: ISO3166-1-Alpha-3 | C3: OMNIA_Region | D3: Sector | E3: Metric | G3: Unit | H3: 1951 | I3: 1952 | J3: 1953 | K3: 1954 | L3: 1955 | M3: 1956 | N3: 1957 | O3: 1958 | P3: 1959 | Q3: 1960 | R3: 1961 | S3: 1962 | T3: 1963 | U3: 1964 | V3: 1965 | W3: 1966 | X3: 1967 | Y3: 1968 | Z3: 1969 | AA3: 1970 | AB3: 1971 | AC3: 1972 | AD3: 1973 | AE3: 1974 | AF3: 1975 | AG3: 1976 | AH3: 1977 | AI3: 1978 | AJ3: 1979 | AK3: 1980 | AL3: 1981 | AM3: 1982 | AN3: 1983 | AO3: 1984 | AP3: 1985 | AQ3: 1986 | AR3: 1987 | AS3: 1988 | AT3: 1989 | AU3: 1990 | AV3: 1991 | AW3: 1992 | AX3: 1993 | AY3: 1994 | AZ3: 1995 | BA3: 1996 | BB3: 1997 | BC3: 1998 | BD3: 1999 | BE3: 2000 | BF3: 2001 | BG3: 2002 | BH3: 2003 | BI3: 2004 | BJ3: 2005 | BK3: 2006 | BL3: 2007 | BM3: 2008 | BN3: 2009 | BO3: 2010 | BP3: 2011 | BQ3: 2012 | BR3: 2013 | BS3: 2014 | BT3: 2015 | BU3: 2016 | BV3: 2017 | BW3: 2018 | BX3: 2019 | BY3: 2020 | BZ3: 2021 | CA3: 2022 | CB3: 2023 | CC3: 2024 | CD3: 2025 | CE3: 2026 | CF3: 2027 | CG3: 2028 | CH3: 2029 | CI3: 2030 | CJ3: 2031 | CK3: 2032 | CL3: 2033 | CM3: 2034 | CN3: 2035 | CO3: 2036 | CP3: 2037 | CQ3: 2038 | CR3: 2039 | CS3: 2040 | CT3: 2041 | CU3: 2042 | CV3: 2043 | CW3: 2044 | CX3: 2045 | CY3: 2046 | CZ3: 2047 | DA3: 2048 | DB3: 2049 | DC3: 2050 | DD3: 2051 | DE3: 2052 | DF3: 2053 | DG3: 2054 | DH3: 2055 | DI3: 2056 | DJ3: 2057 | DK3: 2058 | DL3: 2059 | DM3: 2060 | DN3: 2061 | DO3: 2062 | DP3: 2063 | DQ3: 2064 | DR3: 2065 | DS3: 2066 | DT3: 2067 | DU3: 2068 | DV3: 2069 | DW3: 2070 | DX3: 2071 | DY3: 2072 | DZ3: 2073 | EA3: 2074 | EB3: 2075 | EC3: 2076 | ED3: 2077 | EE3: 2078 | EF3: 2079 | EG3: 2080 | EH3: 2081 | EI3: 2082 | EJ3: 2083 | EK3: 2084 | EL3: 2085 | EM3: 2086 | EN3: 2087 | EO3: 2088 | EP3: 2089 | EQ3: 2090 | ER3: 2091 | ES3: 2092 | ET3: 2093 | EU3: 2094 | EV3: 2095 | EW3: 2096 | EX3: 2097 | EY3: 2098 | EZ3: 2099 | FA3: 2100
A4: Afghanistan | B4: AFG | C4: =VLOOKUP(B4,CountryCodes!$B$4:$C$179,2,FALSE) -> ASC | D4: Total | E4: End-use steel consumption [kt] | F4: EUSC | G4: kt | H4: 3.2708518 | I4: 3.4211707 | J4: 3.7698067 | K4: 4.1087108 | L4: 4.639088 | M4: 4.9758803 | N4: 5.5216654 | O4: 5.2986736 | P4: 6.0645178 | Q4: 6.9875945 | R4: 7.3365826 | S4: 7.7180006 | T4: 13.829594 | U4: 13.035168 | V4: 18.120848 | W4: 13.829499 | X4: 12.572896 | Y4: 12.774002 | Z4: 12.610081 | AA4: 13.580005 | AB4: 21.4474 | AC4: 19.762028 | AD4: 13.760513 | AE4: 15.624339 | AF4: 20.697891 | AG4: 29.60693 | AH4: 56.562522 | AI4: 44.317592 | AJ4: 31.691094 | AK4: 20.231966 | AL4: 18.172787 | AM4: 22.077036 | AN4: 23.682518 | AO4: 33.217145 | AP4: 23.431756 | AQ4: 22.28717 | AR4: 24.946597 | AS4: 17.840378 | AT4: 8.5677399 | AU4: 11.922826 | AV4: 12.570518 | AW4: 12.462457 | AX4: 18.054112 | AY4: 13.491434 | AZ4: 9.7270071 | BA4: 36.207814 | BB4: 39.845181 | BC4: 352.97056 | BD4: 387.8239 | BE4: 18.374023 | BF4: 37.751017 | BG4: 122.02976 | BH4: 235.97314 | BI4: 388.79663 | BJ4: 573.75333 | BK4: 425.89378 | BL4: 423.84572 | BM4: 434.86552 | BN4: 435.18591 | BO4: 647.07231 | BP4: 884.4145 | BQ4: 634.07572 | BR4: 708.27765 | BS4: 685.40556 | BT4: 580.53766 | BU4: 771.62348 | BV4: 731.13417 | BW4: 813.31062 | BX4: 888.7068 | BY4: 972.35208 | BZ4: 1080.9212 | CA4: 929.02142 | CB4: 987.58766 | CC4: 1273.1365 | CD4: 1372.715 | CE4: 1460.2043 | CF4: 1570.2853 | CG4: 1667.0538 | CH4: 1780.9011 | CI4: 1933.5872 | CJ4: 2085.3313 | CK4: 2228.4734 | CL4: 2372.0759 | CM4: 2543.0802 | CN4: 2674.791 | CO4: 2858.2836 | CP4: 3067.783 | CQ4: 3280.6685 | CR4: 3484.7297 | CS4: 3777.6419 | CT4: 4059.0733 | CU4: 4280.7551 | CV4: 4494.4597 | CW4: 4850.5145 | CX4: 5131.0114 | CY4: 5480.5525 | CZ4: 5917.3152 | DA4: 6230.0259 | DB4: 6653.0992 | DC4: 7171.6675 | DD4: 7418.4881 | DE4: 7805.5358 | DF4: 8431.0302 | DG4: 8954.0535 | DH4: 9488.5876 | DI4: 10048.26 | DJ4: 10671.395 | DK4: 11248.103 | DL4: 11748.911 | DM4: 12194.586 | DN4: 12883.778 | DO4: 13410.852 | DP4: 14302.34 | DQ4: 14949.991 | DR4: 15760.274 | DS4: 16449.924 | DT4: 16777.848 | DU4: 17411.561 | DV4: 18345.09 | DW4: 18827.143 | DX4: 19730.288 | DY4: 19879.007 | DZ4: 20631.237 | EA4: 21486.114 | EB4: 21696.848 | EC4: 21823.013 | ED4: 22520.002 | EE4: 23141.155 | EF4: 23254.615 | EG4: 24433.384 | EH4: 24415.728 | EI4: 24181.887 | EJ4: 24527.412 | EK4: 24770.991 | EL4: 25808.45 | EM4: 25672.961 | EN4: 25334.175 | EO4: 26276.223 | EP4: 26150.588 | EQ4: 26337.364 | ER4: 27064.149 | ES4: 26681.857 | ET4: 26837.632 | EU4: 27028.437 | EV4: 27044.486 | EW4: 26996.95 | EX4: 27087.647 | EY4: 27346.407 | EZ4: 27437.333 | FA4: 27557.001
A5: Angola | B5: AGO | C5: =VLOOKUP(B5,CountryCodes!$B$4:$C$179,2,FALSE) -> AFZ | D5: Total | E5: End-use steel consumption [kt] | F5: EUSC | G5: kt | H5: 19.021821 | I5: 19.962786 | J5: 22.058678 | K5: 24.144051 | L5: 27.385261 | M5: 29.515296 | N5: 32.896778 | O5: 31.721385 | P5: 36.335249 | Q5: 42.060943 | R5: 44.339269 | S5: 47.719028 | T5: 38.772388 | U5: 48.165975 | V5: 62.620628 | W5: 91.835974 | X5: 137.21732 | Y5: 156.43913 | Z5: 142.61305 | AA5: 141.21851 | AB5: 195.80918 | AC5: 176.96324 | AD5: 167.1935 | AE5: 173.15888 | AF5: 55.718807 | AG5: 25.008773 | AH5: 60.914525 | AI5: 57.170517 | AJ5: 90.851079 | AK5: 112.21643 | AL5: 145.82518 | AM5: 99.791079 | AN5: 82.329642 | AO5: 104.89189 | AP5: 96.786956 | AQ5: 128.09255 | AR5: 94.02364 | AS5: 124.5549 | AT5: 109.10756 | AU5: 89.951268 | AV5: 145.65356 | AW5: 130.60753 | AX5: 94.057887 | AY5: 74.046498 | AZ5: 73.300167 | BA5: 105.73196 | BB5: 137.70598 | BC5: 163.05485 | BD5: 139.86752 | BE5: 115.36555 | BF5: 199.31446 | BG5: 240.28322 | BH5: 307.22331 | BI5: 382.41683 | BJ5: 531.30548 | BK5: 837.81722 | BL5: 998.38274 | BM5: 1706.3798 | BN5: 1664.7918 | BO5: 1002.3924 | BP5: 1284.6714 | BQ5: 1751.7305 | BR5: 2320.3789 | BS5: 2735.5457 | BT5: 1850.4797 | BU5: 676.65479 | BV5: 887 | BW5: 839 | BX5: 777 | BY5: 473 | BZ5: 470 | CA5: 563 | CB5: 433 | CC5: 2489.108 | CD5: 2615.9313 | CE5: 2747.8125 | CF5: 2892.8073 | CG5: 3040.9281 | CH5: 3206.9278 | CI5: 3382.6812 | CJ5: 3571.0027 | CK5: 3764.5374 | CL5: 3953.1445 | CM5: 4168.1994 | CN5: 4397.8194 | CO5: 4651.5244 | CP5: 4943.2087 | CQ5: 5235.1826 | CR5: 5570.4121 | CS5: 5893.067 | CT5: 6233.9846 | CU5: 6569.3007 | CV5: 6934.0642 | CW5: 7322.836 | CX5: 7711.3879 | CY5: 8115.4633 | CZ5: 8588.9771 | DA5: 9031.1471 | DB5: 9520.148 | DC5: 10028.746 | DD5: 10529.953 | DE5: 11040.784 | DF5: 11613.364 | DG5: 12159.871 | DH5: 12744.32 | DI5: 13334.803 | DJ5: 13902.756 | DK5: 14564.559 | DL5: 15181.221 | DM5: 15824.419 | DN5: 16486.259 | DO5: 17199.472 | DP5: 17823.259 | DQ5: 18563.329 | DR5: 19245.667 | DS5: 19936.246 | DT5: 20639.123 | DU5: 21338.72 | DV5: 22056.258 | DW5: 22781.234 | DX5: 23462.225 | DY5: 24129.988 | DZ5: 24797.968 | EA5: 25501.884 | EB5: 26095.627 | EC5: 26592.64 | ED5: 27181.763 | EE5: 27849.929 | EF5: 28414.549 | EG5: 28804.233 | EH5: 29506.242 | EI5: 29778.416 | EJ5: 30182.582 | EK5: 30548.575 | EL5: 31039.818 | EM5: 31397.785 | EN5: 31713.129 | EO5: 31836.903 | EP5: 32280.587 | EQ5: 32524.758 | ER5: 32635.328 | ES5: 32725.655 | ET5: 32739.952 | EU5: 32841.37 | EV5: 32984.35 | EW5: 33024.274 | EX5: 32986.419 | EY5: 32990.067 | EZ5: 33126.328 | FA5: 32984.629
A6: Albania | B6: ALB | C6: =VLOOKUP(B6,CountryCodes!$B$4:$C$179,2,FALSE) -> ENE | D6: Total | E6: End-use steel consumption [kt] | F6: EUSC | G6: kt | H6: 0.74549868 | I6: 0.78748885 | J6: 0.88854114 | K6: 0.98783097 | L6: 1.1450362 | M6: 1.2454173 | N6: 1.408399 | O6: 1.3421019 | P6: 1.5702737 | Q6: 1.8502647 | R6: 1.9606619 | S6: 2.0124596 | T6: 6.911604 | U6: 6.8964603 | V6: 44.746463 | W6: 41.681187 | X6: 55.357119 | Y6: 51.20039 | Z6: 64.665072 | AA6: 68.251634 | AB6: 68.747965 | AC6: 68.824329 | AD6: 79.580603 | AE6: 78.836249 | AF6: 78.146939 | AG6: 72.349231 | AH6: 87.933717 | AI6: 72.559558 | AJ6: 82.561943 | AK6: 160.83095 | AL6: 136.91969 | AM6: 174.98252 | AN6: 169.80808 | AO6: 194.6273 | AP6: 200.29798 | AQ6: 179.85576 | AR6: 139.75919 | AS6: 206.1298 | AT6: 226.53416 | AU6: 169.67688 | AV6: 57.105078 | AW6: 49.150312 | AX6: 75.290503 | AY6: 89.746176 | AZ6: 105.32068 | BA6: 124.15546 | BB6: 112.65266 | BC6: 130.28819 | BD6: 158.15928 | BE6: 202.70169 | BF6: 348.18995 | BG6: 376.41746 | BH6: 403.14 | BI6: 411.37629 | BJ6: 490.957 | BK6: 565.85352 | BL6: 626.14725 | BM6: 447.27306 | BN6: 465.15789 | BO6: 494.01361 | BP6: 532.57779 | BQ6: 565.84831 | BR6: 561.41707 | BS6: 478.21146 | BT6: 323.14942 | BU6: 367.15607 | BV6: 247 | BW6: 229 | BX6: 300 | BY6: 305 | BZ6: 338 | CA6: 405 | CB6: 418 | CC6: 852.32024 | CD6: 904.88117 | CE6: 952.54723 | CF6: 1004.4368 | CG6: 1055.2121 | CH6: 1094.387 | CI6: 1128.9193 | CJ6: 1149.6799 | CK6: 1165.437 | CL6: 1162.7815 | CM6: 1138.8637 | CN6: 1099.8676 | CO6: 1051.6692 | CP6: 977.9622 | CQ6: 894.27773 | CR6: 803.64067 | CS6: 697.41068 | CT6: 605.86442 | CU6: 510.28986 | CV6: 427.71029 | CW6: 349.06984 | CX6: 286.5505 | CY6: 223.17002 | CZ6: 186.25448 | DA6: 185.14227 | DB6: 182.55046 | DC6: 181.20327 | DD6: 180.16588 | DE6: 180.25509 | DF6: 177.12794 | DG6: 174.45692 | DH6: 171.77603 | DI6: 169.02667 | DJ6: 167.01141 | DK6: 164.00227 | DL6: 162.57821 | DM6: 160.51272 | DN6: 159.65004 | DO6: 159.43316 | DP6: 158.58721 | DQ6: 157.14981 | DR6: 155.95697 | DS6: 153.70889 | DT6: 151.9193 | DU6: 146.77541 | DV6: 142.47408 | DW6: 137.54682 | DX6: 131.78517 | DY6: 125.66862 | DZ6: 119.9702 | EA6: 114.97998 | EB6: 108.51464 | EC6: 104.9644 | ED6: 101.96654 | EE6: 97.906173 | EF6: 95.82864 | EG6: 93.737341 | EH6: 90.789274 | EI6: 89.074213 | EJ6: 87.060457 | EK6: 85.696006 | EL6: 84.685811 | EM6: 86.548889 | EN6: 96.569897 | EO6: 108.01736 | EP6: 115.37672 | EQ6: 125.74404 | ER6: 136.58031 | ES6: 146.72155 | ET6: 156.35235 | EU6: 166.02527 | EV6: 175.02874 | EW6: 183.47632 | EX6: 190.31446 | EY6: 196.51824 | EZ6: 201.71883 | FA6: 206.4591
A7: United Arab Emirates | B7: ARE | C7: =VLOOKUP(B7,CountryCodes!$B$4:$C$179,2,FALSE) -> MEA | D7: Total | E7: End-use steel consumption [kt] | F7: EUSC | G7: kt | H7: 0 | I7: 0 | J7: 0 | K7: 0 | L7: 0 | M7: 0 | N7: 0 | O7: 0 | P7: 0 | Q7: 0 | R7: 0 | S7: 0 | T7: 0 | U7: 0 | V7: 0 | W7: 0 | X7: 0 | Y7: 0 | Z7: 0 | AA7: 41.227136 | AB7: 40.940422 | AC7: 172.29437 | AD7: 308.16927 | AE7: 430.49758 | AF7: 585.91811 | AG7: 1103.7393 | AH7: 1036.1272 | AI7: 821.01708 | AJ7: 1025.8673 | AK7: 1058.9408 | AL7: 1173.9758 | AM7: 1208.8475 | AN7: 895.43065 | AO7: 593.34599 | AP7: 569.35128 | AQ7: 494.62056 | AR7: 464.40449 | AS7: 495.8474 | AT7: 782.27329 | AU7: 876.51203 | AV7: 1009.4724 | AW7: 1205.0671 | AX7: 1223.3172 | AY7: 1963.6368 | AZ7: 1824.298 | BA7: 2103.596 | BB7: 1635.0388 | BC7: 3515.8931 | BD7: 2684.6471 | BE7: 2622.6776 | BF7: 2869.6262 | BG7: 3593.9411 | BH7: 4213.8378 | BI7: 4494.4529 | BJ7: 5134.6335 | BK7: 8435.9665 | BL7: 9777.4632 | BM7: 13417.796 | BN7: 6684.49 | BO7: 4146.5722 | BP7: 3997.4126 | BQ7: 6351.4296 | BR7: 6541.8757 | BS7: 7081.7787 | BT7: 7487.677 | BU7: 7405.71 | BV7: 9735 | BW7: 9305 | BX7: 9375 | BY7: 6340 | BZ7: 5102 | CA7: 6056 | CB7: 7044 | CC7: 8126.5995 | CD7: 8210.3324 | CE7: 6926.0755 | CF7: 6135.1896 | CG7: 5747.6477 | CH7: 5564.787 | CI7: 5657.2895 | CJ7: 5922.0703 | CK7: 6271.6824 | CL7: 6506.4399 | CM7: 6603.8484 | CN7: 6602.3061 | CO7: 6569.373 | CP7: 6577.4329 | CQ7: 6645.9446 | CR7: 6768.0338 | CS7: 6895.6778 | CT7: 7012.581 | CU7: 7107.8051 | CV7: 7190.222 | CW7: 7276.7053 | CX7: 7377.0191 | CY7: 7482.0843 | CZ7: 7615.1526 | DA7: 7753.2806 | DB7: 7838.4896 | DC7: 7918.1213 | DD7: 7986.5441 | DE7: 8077.2219 | DF7: 8201.3916 | DG7: 8352.8828 | DH7: 8523.0372 | DI7: 8676.2167 | DJ7: 8835.6192 | DK7: 8999.5039 | DL7: 9160.0891 | DM7: 9314.3165 | DN7: 9459.2456 | DO7: 9623.8543 | DP7: 9789.9141 | DQ7: 9945.5724 | DR7: 10101.658 | DS7: 10250.837 | DT7: 10401.842 | DU7: 10563.475 | DV7: 10722.511 | DW7: 10883.932 | DX7: 11029.63 | DY7: 11181.174 | DZ7: 11314.235 | EA7: 11454.047 | EB7: 11565.69 | EC7: 11682.841 | ED7: 11792.136 | EE7: 11895.28 | EF7: 11989.017 | EG7: 12083.487 | EH7: 12173.252 | EI7: 12264.648 | EJ7: 12351.749 | EK7: 12438.044 | EL7: 12516.848 | EM7: 12598.887 | EN7: 12686.352 | EO7: 12776.284 | EP7: 12861.78 | EQ7: 12950.665 | ER7: 13029.2 | ES7: 13116.703 | ET7: 13206.15 | EU7: 13299.02 | EV7: 13393.506 | EW7: 13489.377 | EX7: 13588.208 | EY7: 13686.409 | EZ7: 13791.649 | FA7: 13890.326
A8: Argentina | B8: ARG | C8: =VLOOKUP(B8,CountryCodes!$B$4:$C$179,2,FALSE) -> LAM | D8: Total | E8: End-use steel consumption [kt] | F8: EUSC | G8: kt | H8: 482.14224 | I8: 500.1289 | J8: 551.37347 | K8: 586.67868 | L8: 672.50566 | M8: 699.07316 | N8: 780.89809 | O8: 768.52055 | P8: 839.4346 | Q8: 1081.8612 | R8: 1312.0413 | S8: 1430.2568 | T8: 943.56621 | U8: 1384.4841 | V8: 1966.914 | W8: 1417.1571 | X8: 1362.7497 | Y8: 1562.2361 | Z8: 2394.0533 | AA8: 2419.6193 | AB8: 2515.3698 | AC8: 2608.0172 | AD8: 2606.3086 | AE8: 2637.2684 | AF8: 2924.9858 | AG8: 2245.8973 | AH8: 2733.8423 | AI8: 2092.7999 | AJ8: 2990.125 | AK8: 2780.7765 | AL8: 2134.8787 | AM8: 2189.813 | AN8: 2378.5878 | AO8: 2214.6364 | AP8: 1813.9436 | AQ8: 1892.2265 | AR8: 2499.5424 | AS8: 2317.2544 | AT8: 1432.11 | AU8: 1307.5433 | AV8: 1639.8445 | AW8: 2574.9242 | AX8: 2497.5174 | AY8: 3226.5093 | AZ8: 2677.1975 | BA8: 3125.2661 | BB8: 3930.2512 | BC8: 3966.4512 | BD8: 2869.0918 | BE8: 2752.4018 | BF8: 2346.2797 | BG8: 1529.6078 | BH8: 2577.9846 | BI8: 3524.7417 | BJ8: 3746.6472 | BK8: 4177.2223 | BL8: 4400.927 | BM8: 4860.9219 | BN8: 2697.5284 | BO8: 4832.0198 | BP8: 5413.5636 | BQ8: 4664.6203 | BR8: 4960.6388 | BS8: 4842.2877 | BT8: 5222.039 | BU8: 4317.4962 | BV8: 6494 | BW8: 6271 | BX8: 4829 | BY8: 3595 | BZ8: 5037 | CA8: 5084 | CB8: 4987 | CC8: 6489.6642 | CD8: 6699.6196 | CE8: 6896.7527 | CF8: 7107.3216 | CG8: 7332.2098 | CH8: 7564.1491 | CI8: 7806.5686 | CJ8: 8050.2056 | CK8: 8290.8782 | CL8: 8526.8751 | CM8: 8769.5927 | CN8: 9019.6699 | CO8: 9276.9598 | CP8: 9545.2885 | CQ8: 9817.2433 | CR8: 10084.231 | CS8: 10337.737 | CT8: 10586.286 | CU8: 10824.265 | CV8: 11058.722 | CW8: 11293.627 | CX8: 11524.457 | CY8: 11747.516 | CZ8: 11959.088 | DA8: 12162.598 | DB8: 12355.69 | DC8: 12542.091 | DD8: 12711.183 | DE8: 12859.995 | DF8: 12994.537 | DG8: 13109.203 | DH8: 13213.381 | DI8: 13293.334 | DJ8: 13355.286 | DK8: 13407.335 | DL8: 13447.176 | DM8: 13484.313 | DN8: 13500.733 | DO8: 13511.778 | DP8: 13511.666 | DQ8: 13499.631 | DR8: 13472.896 | DS8: 13431.43 | DT8: 13378.98 | DU8: 13305.607 | DV8: 13205.193 | DW8: 13092.7 | DX8: 12971.191 | DY8: 12828.03 | DZ8: 12681.741 | EA8: 12512.597 | EB8: 12326.963 | EC8: 12148.081 | ED8: 11950.323 | EE8: 11757.03 | EF8: 11539.988 | EG8: 11332.448 | EH8: 11120.551 | EI8: 10910.331 | EJ8: 10698.234 | EK8: 10494.719 | EL8: 10303.239 | EM8: 10112.696 | EN8: 9941.1841 | EO8: 9780.4196 | EP8: 9626.4671 | EQ8: 9477.975 | ER8: 9338.9815 | ES8: 9219.8983 | ET8: 9110.6695 | EU8: 9017.1026 | EV8: 8941.4212 | EW8: 8865.0099 | EX8: 8805.1927 | EY8: 8757.5353 | EZ8: 8717.749 | FA8: 8684.2957
A9: Armenia | B9: ARM | C9: =VLOOKUP(B9,CountryCodes!$B$4:$C$179,2,FALSE) -> ASC | D9: Total | E9: End-use steel consumption [kt] | F9: EUSC | G9: kt | H9: 0.061162843 | I9: 0.063923748 | J9: 0.069725365 | K9: 0.075456068 | L9: 0.084203198 | M9: 0.09018005 | N9: 0.099357279 | O9: 0.096941551 | P9: 0.10917817 | Q9: 0.12411192 | R9: 0.13084524 | S9: 0.14075101 | T9: 0.19909899 | U9: 0.17656281 | V9: 0.13770349 | W9: 0.095685799 | X9: 0.65184017 | Y9: 0.52099237 | Z9: 0.45496666 | AA9: 0.26676306 | AB9: 0.18764132 | AC9: 0.1885962 | AD9: 0.27281548 | AE9: 0.40898966 | AF9: 0.52761583 | AG9: 0.73837447 | AH9: 0.5942982 | AI9: 0.6440068 | AJ9: 0.66831332 | AK9: 0.63195852 | AL9: 0.72899451 | AM9: 0.88851048 | AN9: 1.0550016 | AO9: 0.99252918 | AP9: 1.0059439 | AQ9: 0.99307825 | AR9: 0.85427544 | AS9: 0.82587805 | AT9: 0.88300238 | AU9: 0.69382455 | AV9: 0.73641824 | AW9: 0.50741402 | AX9: 2.3175249 | AY9: 0.62647729 | AZ9: 0.75100669 | BA9: 2.6939708 | BB9: 2.6187235 | BC9: 0.56579167 | BD9: 31.72739 | BE9: 11.287821 | BF9: 21.960129 | BG9: 44.825914 | BH9: 73.730763 | BI9: 59.614347 | BJ9: 81.614592 | BK9: 135.6323 | BL9: 158.51012 | BM9: 197.31902 | BN9: 154.38698 | BO9: 188.28704 | BP9: 152.34797 | BQ9: 147.77189 | BR9: 159.50339 | BS9: 187.23304 | BT9: 204.00684 | BU9: 185.00404 | BV9: 193.99093 | BW9: 212.25649 | BX9: 234.2557 | BY9: 256.58843 | BZ9: 269.33413 | CA9: 291.31936 | CB9: 399.49854 | CC9: 495.13084 | CD9: 394.61586 | CE9: 426.71943 | CF9: 462.61479 | CG9: 502.44472 | CH9: 542.33049 | CI9: 583.43667 | CJ9: 627.38165 | CK9: 671.73877 | CL9: 719.68876 | CM9: 766.57661 | CN9: 815.834 | CO9: 862.50966 | CP9: 910.53489 | CQ9: 955.00807 | CR9: 997.01389 | CS9: 1029.0194 | CT9: 1061.9109 | CU9: 1089.6951 | CV9: 1107.8219 | CW9: 1122.1888 | CX9: 1130.8525 | CY9: 1127.0962 | CZ9: 1115.383 | DA9: 1096.6317 | DB9: 1072.1683 | DC9: 1042.3107 | DD9: 1008.8978 | DE9: 967.52998 | DF9: 924.33266 | DG9: 893.03983 | DH9: 838.95106 | DI9: 801.18977 | DJ9: 755.56199 | DK9: 709.52319 | DL9: 675.26104 | DM9: 632.41568 | DN9: 598.20387 | DO9: 564.84676 | DP9: 539.4107 | DQ9: 507.04102 | DR9: 484.96133 | DS9: 482.77009 | DT9: 481.2521 | DU9: 479.63228 | DV9: 477.62614 | DW9: 476.73725 | DX9: 475.52615 | DY9: 474.2323 | DZ9: 472.51856 | EA9: 470.96892 | EB9: 470.42089 | EC9: 469.7162 | ED9: 470.04839 | EE9: 468.26789 | EF9: 466.4777 | EG9: 465.48376 | EH9: 463.53785 | EI9: 461.36646 | EJ9: 459.21238 | EK9: 457.87659 | EL9: 454.9264 | EM9: 451.93006 | EN9: 448.01654 | EO9: 459.61106 | EP9: 469.62812 | EQ9: 478.69265 | ER9: 486.41063 | ES9: 494.35996 | ET9: 503.75033 | EU9: 510.0476 | EV9: 517.40267 | EW9: 526.95434 | EX9: 534.18311 | EY9: 539.90821 | EZ9: 546.21187 | FA9: 553.09542
A10: Australia | B10: AUS | C10: =VLOOKUP(B10,CountryCodes!$B$4:$C$179,2,FALSE) -> ANZ | D10: Total | E10: End-use steel consumption [kt] | F10: EUSC | G10: kt | H10: 898.01085 | I10: 1035.0581 | J10: 1368.4865 | K10: 1454.5396 | L10: 1420.9192 | M10: 1523.5779 | N10: 2032.1617 | O10: 2138.8795 | P10: 2326.0022 | Q10: 2592.8585 | R10: 2636.1826 | S10: 2910.4182 | T10: 2821.7765 | U10: 3801.28 | V10: 4374.0944 | W10: 4001.8711 | X10: 4698.403 | Y10: 5106.552 | Z10: 5245.6894 | AA10: 5529.4827 | AB10: 5817.6316 | AC10: 4932.2541 | AD10: 6123.3665 | AE10: 6545.3707 | AF10: 5519.7468 | AG10: 5332.6834 | AH10: 4872.7432 | AI10: 5033.9709 | AJ10: 5985.3507 | AK10: 5795.19 | AL10: 6195.8094 | AM10: 5455.0175 | AN10: 4440.2392 | AO10: 5742.5929 | AP10: 5634.8259 | AQ10: 5593.6254 | AR10: 5008.7895 | AS10: 5855.9777 | AT10: 6432.0987 | AU10: 4964.9326 | AV10: 4300.5769 | AW10: 4332.0856 | AX10: 5541.3309 | AY10: 5919.5193 | AZ10: 5689.8982 | BA10: 5747.1134 | BB10: 6480.8527 | BC10: 6019.244 | BD10: 5582.8522 | BE10: 4034.9472 | BF10: 4276.3082 | BG10: 5433.9835 | BH10: 6431.9203 | BI10: 7767.0255 | BJ10: 8978.5728 | BK10: 8835.8971 | BL10: 9345.6411 | BM10: 9727.5178 | BN10: 6935.0201 | BO10: 9597.7787 | BP10: 9174.3412 | BQ10: 9806.976 | BR10: 8901.5682 | BS10: 8864.3278 | BT10: 9150.3786 | BU10: 8812.3029 | BV10: 10439 | BW10: 10456 | BX10: 10500 | BY10: 5100 | BZ10: 6156 | CA10: 6140 | CB10: 6439 | CC10: 11856.326 | CD10: 11821.244 | CE10: 11532.597 | CF10: 11065.73 | CG10: 10664.897 | CH10: 10305.476 | CI10: 10011.991 | CJ10: 9942.5613 | CK10: 9846.9107 | CL10: 9678.1939 | CM10: 9526.0782 | CN10: 9404.2645 | CO10: 9400.0006 | CP10: 9460.0434 | CQ10: 9504.6943 | CR10: 9742.366 | CS10: 9810.5363 | CT10: 9977.5485 | CU10: 10104.769 | CV10: 10210.686 | CW10: 10248.559 | CX10: 10341.304 | CY10: 10502.578 | CZ10: 10702.25 | DA10: 10652.914 | DB10: 10925.741 | DC10: 10875.215 | DD10: 10986.285 | DE10: 11072.737 | DF10: 11115.734 | DG10: 11223.195 | DH10: 11355.635 | DI10: 11447.471 | DJ10: 11442.741 | DK10: 11519.134 | DL10: 11690.137 | DM10: 11627.258 | DN10: 11720.585 | DO10: 11882.361 | DP10: 12004.033 | DQ10: 12152.89 | DR10: 12123.079 | DS10: 12321.71 | DT10: 12547.652 | DU10: 12673.29 | DV10: 12794.296 | DW10: 12870.908 | DX10: 12894.628 | DY10: 12891.153 | DZ10: 12989.721 | EA10: 13110.146 | EB10: 13242.683 | EC10: 13307.252 | ED10: 13373.279 | EE10: 13537.217 | EF10: 13605.303 | EG10: 13681.292 | EH10: 13764.236 | EI10: 13982.576 | EJ10: 13976.44 | EK10: 14157.428 | EL10: 14082.603 | EM10: 14187.293 | EN10: 14357.905 | EO10: 14530.29 | EP10: 14770.03 | EQ10: 14743.653 | ER10: 14919.209 | ES10: 15007.82 | ET10: 15025.485 | EU10: 15065.913 | EV10: 14970.45 | EW10: 15128.841 | EX10: 15312.092 | EY10: 15451.349 | EZ10: 15341.561 | FA10: 15333.875
A11: Austria | B11: AUT | C11: =VLOOKUP(B11,CountryCodes!$B$4:$C$179,2,FALSE) -> EUW | D11: Total | E11: End-use steel consumption [kt] | F11: EUSC | G11: kt | H11: 230.06262 | I11: 302.47549 | J11: 409.17715 | K11: 665.55808 | L11: 768.79409 | M11: 968.05395 | N11: 1290.0256 | O11: 1176.3131 | P11: 1237.2406 | Q11: 1744.6785 | R11: 1659.8734 | S11: 1504.3572 | T11: 1144.0422 | U11: 1355.9595 | V11: 1475.2967 | W11: 1482.2691 | X11: 1349.3408 | Y11: 1685.3261 | Z11: 1850.7941 | AA11: 2217.8595 | AB11: 2096.4791 | AC11: 2241.3522 | AD11: 2561.9486 | AE11: 2670.4535 | AF11: 1751.7226 | AG11: 2296.2571 | AH11: 2212.2175 | AI11: 2280.1307 | AJ11: 2419.7613 | AK11: 2355.8724 | AL11: 2049.5787 | AM11: 1701.2891 | AN11: 1732.0654 | AO11: 1725.384 | AP11: 1593.9916 | AQ11: 1871.2852 | AR11: 1683.7593 | AS11: 1922.1025 | AT11: 2212.148 | AU11: 1975.9557 | AV11: 2269.0223 | AW11: 2074.5636 | AX11: 1918.7653 | AY11: 2670.4318 | AZ11: 2443.2883 | BA11: 1343.7373 | BB11: 2726.8571 | BC11: 2083.7122 | BD11: 2356.2368 | BE11: 2758.8946 | BF11: 2617.9057 | BG11: 2529.992 | BH11: 2420.9627 | BI11: 887.48346 | BJ11: 2707.5836 | BK11: 2902.896 | BL11: 3236.5276 | BM11: 2868.6182 | BN11: 1972.2521 | BO11: 2159.3067 | BP11: 2602.6077 | BQ11: 2812.1605 | BR11: 2765.1573 | BS11: 2829.2193 | BT11: 2771.1718 | BU11: 2755.1682 | BV11: 4329 | BW11: 4491 | BX11: 4370 | BY11: 3649 | BZ11: 4497 | CA11: 4103 | CB11: 3089 | CC11: 1541.9246 | CD11: 1687.5147 | CE11: 1793.6628 | CF11: 1886.5526 | CG11: 1967.3053 | CH11: 2034.7759 | CI11: 2059.6094 | CJ11: 2116.8405 | CK11: 2210.0068 | CL11: 2279.8539 | CM11: 2351.4921 | CN11: 2333.652 | CO11: 2336.3038 | CP11: 2316.4952 | CQ11: 2260.0029 | CR11: 2310.1147 | CS11: 2290.4947 | CT11: 2306.757 | CU11: 2330.7285 | CV11: 2325.5818 | CW11: 2336.3332 | CX11: 2310.3335 | CY11: 2322.4054 | CZ11: 2304.8094 | DA11: 2285.6956 | DB11: 2263.5864 | DC11: 2232.3395 | DD11: 2229.5837 | DE11: 2235.1208 | DF11: 2217.1053 | DG11: 2196.8111 | DH11: 2212.3201 | DI11: 2230.282 | DJ11: 2245.5631 | DK11: 2224.5948 | DL11: 2244.7619 | DM11: 2249.4508 | DN11: 2261.5989 | DO11: 2269.0973 | DP11: 2256.387 | DQ11: 2258.7764 | DR11: 2286.9437 | DS11: 2264.3485 | DT11: 2274.5212 | DU11: 2300.6221 | DV11: 2319.4946 | DW11: 2327.3595 | DX11: 2362.6692 | DY11: 2381.3769 | DZ11: 2373.9188 | EA11: 2399.7491 | EB11: 2391.2547 | EC11: 2413.0128 | ED11: 2403.2252 | EE11: 2364.0109 | EF11: 2368.5029 | EG11: 2374.9607 | EH11: 2382.8218 | EI11: 2360.4778 | EJ11: 2341.8566 | EK11: 2329.9792 | EL11: 2308.7514 | EM11: 2314.372 | EN11: 2322.7114 | EO11: 2326.0559 | EP11: 2297.812 | EQ11: 2288.9288 | ER11: 2304.4287 | ES11: 2301.5775 | ET11: 2313.6594 | EU11: 2303.2011 | EV11: 2307.8593 | EW11: 2280.4932 | EX11: 2275.314 | EY11: 2256.3274 | EZ11: 2264.9305 | FA11: 2254.5768
A12: Azerbaijan | B12: AZE | C12: =VLOOKUP(B12,CountryCodes!$B$4:$C$179,2,FALSE) -> ASC | D12: Total | E12: End-use steel consumption [kt] | F12: EUSC | G12: kt | H12: 1.4207462 | I12: 1.4885087 | J12: 1.6199344 | K12: 1.7532268 | L12: 1.9528003 | M12: 2.0960236 | N12: 2.3063007 | O12: 2.2673733 | P12: 2.5335099 | Q12: 2.8744418 | R12: 3.0430687 | S12: 3.2717677 | T12: 3.5535624 | U12: 2.203261 | V12: 1.9190274 | W12: 1.4221805 | X12: 23.387525 | Y12: 19.05381 | Z12: 13.487193 | AA12: 5.9157858 | AB12: 5.0147311 | AC12: 6.1338067 | AD12: 8.8010771 | AE12: 13.144091 | AF12: 13.362429 | AG12: 17.776316 | AH12: 14.035575 | AI12: 16.459548 | AJ12: 19.034368 | AK12: 18.530155 | AL12: 19.145184 | AM12: 20.993796 | AN12: 24.165387 | AO12: 26.622456 | AP12: 29.654576 | AQ12: 28.193467 | AR12: 28.656932 | AS12: 25.64204 | AT12: 24.03782 | AU12: 17.49365 | AV12: 15.308761 | AW12: 13.698326 | AX12: 27.094281 | AY12: 14.717407 | AZ12: 48.165155 | BA12: 178.92331 | BB12: 174.14871 | BC12: 269.62256 | BD12: 188.25513 | BE12: 172.11639 | BF12: 224.75069 | BG12: 337.95939 | BH12: 609.39367 | BI12: 669.01826 | BJ12: 720.82957 | BK12: 874.2164 | BL12: 897.89942 | BM12: 1088.1312 | BN12: 916.84257 | BO12: 953.51095 | BP12: 1198.426 | BQ12: 1278.6362 | BR12: 1382.6445 | BS12: 1327.9073 | BT12: 1333.8696 | BU12: 821.00395 | BV12: 580 | BW12: 763 | BX12: 867 | BY12: 752 | BZ12: 606 | CA12: 600 | CB12: 1011 | CC12: 2195.4448 | CD12: 2595.2122 | CE12: 2755.2046 | CF12: 2918.1337 | CG12: 3083.9182 | CH12: 3258.9241 | CI12: 3438.0584 | CJ12: 3615.463 | CK12: 3791.5348 | CL12: 3962.4013 | CM12: 4126.0757 | CN12: 4290.0788 | CO12: 4452.5606 | CP12: 4604.1325 | CQ12: 4745.06 | CR12: 4859.0115 | CS12: 4958.8412 | CT12: 5019.8879 | CU12: 5058.9499 | CV12: 5073.4878 | CW12: 5068.6906 | CX12: 5035.0572 | CY12: 5000.2718 | CZ12: 4925.2921 | DA12: 4856.0525 | DB12: 4758.7615 | DC12: 4636.3707 | DD12: 4535.2184 | DE12: 4411.6792 | DF12: 4289.6688 | DG12: 4151.9014 | DH12: 4027.1421 | DI12: 3886.375 | DJ12: 3753.5346 | DK12: 3624.942 | DL12: 3526.8196 | DM12: 3412.9568 | DN12: 3310.2948 | DO12: 3223.2853 | DP12: 3162.8671 | DQ12: 3089.7283 | DR12: 3024.3801 | DS12: 2955.3845 | DT12: 2910.4628 | DU12: 2850.8555 | DV12: 2808.7716 | DW12: 2772.0067 | DX12: 2719.5462 | DY12: 2690.5749 | DZ12: 2666.2501 | EA12: 2640.3659 | EB12: 2637.5073 | EC12: 2614.4664 | ED12: 2623.5329 | EE12: 2617.9387 | EF12: 2632.5467 | EG12: 2630.5088 | EH12: 2642.2541 | EI12: 2663.5875 | EJ12: 2690.3516 | EK12: 2726.7607 | EL12: 2749.3827 | EM12: 2777.0197 | EN12: 2815.7679 | EO12: 2842.8448 | EP12: 2882.6086 | EQ12: 2913.921 | ER12: 2942.6091 | ES12: 2982.4055 | ET12: 3013.4408 | EU12: 3041.567 | EV12: 3070.1179 | EW12: 3094.7557 | EX12: 3131.7203 | EY12: 3152.8028 | EZ12: 3173.3552 | FA12: 3198.426
A13: Burundi | B13: BDI | C13: =VLOOKUP(B13,CountryCodes!$B$4:$C$179,2,FALSE) -> AFE | D13: Total | E13: End-use steel consumption [kt] | F13: EUSC | G13: kt | H13: 0.91973203 | I13: 0.96110897 | J13: 1.0572024 | K13: 1.1505413 | L13: 1.2966299 | M13: 1.3892861 | N13: 1.5394232 | O13: 1.4776566 | P13: 1.6884789 | Q13: 1.9421948 | R13: 2.0377127 | S13: 2.1468664 | T13: 3.8974846 | U13: 3.48227 | V13: 6.7972694 | W13: 2.5446893 | X13: 3.3698517 | Y13: 5.0765859 | Z13: 3.3489509 | AA13: 4.3604032 | AB13: 4.0102129 | AC13: 4.6181685 | AD13: 3.9633784 | AE13: 5.8320908 | AF13: 3.7487063 | AG13: 6.1088109 | AH13: 8.5776489 | AI13: 10.217333 | AJ13: 10.824604 | AK13: 9.8732158 | AL13: 13.166039 | AM13: 20.109481 | AN13: 13.574315 | AO13: 21.550054 | AP13: 14.502133 | AQ13: 16.793082 | AR13: 18.208819 | AS13: 12.988069 | AT13: 12.039814 | AU13: 19.680909 | AV13: 13.403788 | AW13: 15.134595 | AX13: 17.119653 | AY13: 13.975561 | AZ13: 16.077488 | BA13: 7.6269628 | BB13: 7.8343761 | BC13: 13.167712 | BD13: 12.227963 | BE13: 15.955882 | BF13: 12.159272 | BG13: 13.834518 | BH13: 14.427015 | BI13: 18.698614 | BJ13: 25.775272 | BK13: 23.081197 | BL13: 31.79493 | BM13: 27.377278 | BN13: 43.089956 | BO13: 48.628751 | BP13: 49.076909 | BQ13: 46.096485 | BR13: 40.710394 | BS13: 36.789779 | BT13: 32.539571 | BU13: 44.704376 | BV13: 47.547551 | BW13: 52.592521 | BX13: 65.296542 | BY13: 64.785255 | BZ13: 66.471032 | CA13: 69.584445 | CB13: 75.21255 | CC13: 79.803772 | CD13: 81.751204 | CE13: 85.21575 | CF13: 89.510019 | CG13: 95.563469 | CH13: 102.70933 | CI13: 106.89225 | CJ13: 112.81712 | CK13: 120.39685 | CL13: 127.24048 | CM13: 134.59504 | CN13: 141.97229 | CO13: 150.53486 | CP13: 161.59904 | CQ13: 171.67065 | CR13: 181.20042 | CS13: 192.15961 | CT13: 202.68624 | CU13: 213.10422 | CV13: 229.62844 | CW13: 240.99556 | CX13: 256.39379 | CY13: 270.0639 | CZ13: 279.52849 | DA13: 302.12016 | DB13: 316.88145 | DC13: 341.45714 | DD13: 354.35838 | DE13: 378.10575 | DF13: 403.18971 | DG13: 428.55996 | DH13: 456.47015 | DI13: 480.67815 | DJ13: 513.90814 | DK13: 542.21162 | DL13: 577.60718 | DM13: 618.50795 | DN13: 658.39593 | DO13: 703.65362 | DP13: 751.00218 | DQ13: 798.07982 | DR13: 856.41456 | DS13: 929.10965 | DT13: 984.94591 | DU13: 1059.0761 | DV13: 1126.6275 | DW13: 1206.6569 | DX13: 1298.2483 | DY13: 1369.967 | DZ13: 1480.7019 | EA13: 1590.0563 | EB13: 1697.1863 | EC13: 1832.1468 | ED13: 1943.9334 | EE13: 2110.8639 | EF13: 2248.7484 | EG13: 2409.8818 | EH13: 2559.6655 | EI13: 2779.8827 | EJ13: 2967.612 | EK13: 3150.9674 | EL13: 3391.6211 | EM13: 3655.76 | EN13: 3878.4251 | EO13: 4126.1327 | EP13: 4443.2228 | EQ13: 4746.2077 | ER13: 5003.9904 | ES13: 5317.8783 | ET13: 5652.5439 | EU13: 5990.1613 | EV13: 6373.4827 | EW13: 6648.2958 | EX13: 6988.0247 | EY13: 7340.3193 | EZ13: 7697.0262 | FA13: 7972.5022
A14: Belgium | B14: BEL | C14: =VLOOKUP(B14,CountryCodes!$B$4:$C$179,2,FALSE) -> EUW | D14: Total | E14: End-use steel consumption [kt] | F14: EUSC | G14: kt | H14: 3004.4751 | I14: 2781.8564 | J14: 1902.7175 | K14: 2256.358 | L14: 2941.5536 | M14: 3252.7429 | N14: 2892.8435 | O14: 2721.0115 | P14: 2727.2572 | Q14: 3200.4783 | R14: 2842.1686 | S14: 1296.0136 | T14: 2973.6327 | U14: 3596.2857 | V14: 3373.5401 | W14: 3484.4651 | X14: 3891.1191 | Y14: 4277.7619 | Z14: 5312.3204 | AA14: 5222.1112 | AB14: 5224.7071 | AC14: 5483.4895 | AD14: 6114.3637 | AE14: 6490.3925 | AF14: 4019.9048 | AG14: 4985.4059 | AH14: 4315.945 | AI14: 4574.9856 | AJ14: 4833.8384 | AK14: 4129.3488 | AL14: 3592.1206 | AM14: 3123.6213 | AN14: 3119.6771 | AO14: 3599.3802 | AP14: 2908.8809 | AQ14: 2797.7466 | AR14: 1346.6049 | AS14: 3087.4613 | AT14: 2871.8489 | AU14: 2944.7449 | AV14: 2859.8319 | AW14: 2517.6453 | AX14: 2541.6103 | AY14: 3055.0966 | AZ14: 3185.4085 | BA14: 2484.56 | BB14: 3101.3847 | BC14: 3663.392 | BD14: 2804.1711 | BE14: 3402.3242 | BF14: 2160.2851 | BG14: 1848.4484 | BH14: 2708.8077 | BI14: 3673.4656 | BJ14: 3395.2047 | BK14: 3900.6502 | BL14: 4438.7652 | BM14: 3223.4595 | BN14: 489.05495 | BO14: 1289.8932 | BP14: 2189.9297 | BQ14: 2116.7128 | BR14: 511.3597 | BS14: 1246.3607 | BT14: 1782.0112 | BU14: 3392.7384 | BV14: 2504.7425 | BW14: 2676.6287 | BX14: 2926.5555 | BY14: 3144.1041 | BZ14: 2448.3372 | CA14: 2396.0537 | CB14: 4072.827 | CC14: 2476.8886 | CD14: 2347.8989 | CE14: 2294.8304 | CF14: 2293.7325 | CG14: 2342.66 | CH14: 2403.4523 | CI14: 2460.62 | CJ14: 2488.1584 | CK14: 2527.7783 | CL14: 2575.1684 | CM14: 2629.0814 | CN14: 2641.0356 | CO14: 2664.0853 | CP14: 2689.1762 | CQ14: 2728.2489 | CR14: 2737.6373 | CS14: 2741.8189 | CT14: 2759.0341 | CU14: 2799.893 | CV14: 2802.1673 | CW14: 2816.0075 | CX14: 2832.7509 | CY14: 2809.2943 | CZ14: 2798.887 | DA14: 2776.7813 | DB14: 2744.4194 | DC14: 2712.9165 | DD14: 2688.202 | DE14: 2641.4988 | DF14: 2592.592 | DG14: 2563.5605 | DH14: 2568.04 | DI14: 2555.7652 | DJ14: 2530.4378 | DK14: 2506.0365 | DL14: 2567.8474 | DM14: 2539.7391 | DN14: 2539.3847 | DO14: 2487.9213 | DP14: 2508.6176 | DQ14: 2502.4897 | DR14: 2508.0374 | DS14: 2517.3288 | DT14: 2527.6629 | DU14: 2539.9792 | DV14: 2525.6109 | DW14: 2537.4075 | DX14: 2531.2889 | DY14: 2571.5848 | DZ14: 2566.7807 | EA14: 2556.334 | EB14: 2550.1202 | EC14: 2561.4674 | ED14: 2559.2382 | EE14: 2521.6835 | EF14: 2480.6957 | EG14: 2495.5393 | EH14: 2464.5794 | EI14: 2490.6854 | EJ14: 2435.1086 | EK14: 2446.0655 | EL14: 2423.9152 | EM14: 2420.2421 | EN14: 2396.2539 | EO14: 2364.1215 | EP14: 2357.703 | EQ14: 2364.9061 | ER14: 2356.5041 | ES14: 2348.4955 | ET14: 2306.7055 | EU14: 2310.9008 | EV14: 2285.2573 | EW14: 2289.6367 | EX14: 2291.9789 | EY14: 2271.9254 | EZ14: 2228.2815 | FA14: 2219.0377
A15: Benin | B15: BEN | C15: =VLOOKUP(B15,CountryCodes!$B$4:$C$179,2,FALSE) -> AFW | D15: Total | E15: End-use steel consumption [kt] | F15: EUSC | G15: kt | H15: 3.2954465 | I15: 3.4502188 | J15: 3.7863688 | K15: 4.1173816 | L15: 4.6288257 | M15: 4.9645459 | N15: 5.4938093 | O15: 5.3046351 | P15: 6.0255209 | Q15: 6.9219327 | R15: 7.2850272 | S15: 7.4296008 | T15: 14.614897 | U15: 14.753001 | V15: 11.111127 | W15: 7.5526442 | X15: 10.815732 | Y15: 10.724624 | Z15: 16.470943 | AA15: 15.752198 | AB15: 15.888823 | AC15: 21.72448 | AD15: 15.182649 | AE15: 22.752981 | AF15: 18.004166 | AG15: 21.831077 | AH15: 21.865495 | AI15: 19.098253 | AJ15: 35.008451 | AK15: 29.541943 | AL15: 39.027583 | AM15: 40.016801 | AN15: 15.990503 | AO15: 17.13714 | AP15: 17.373811 | AQ15: 18.540068 | AR15: 16.686849 | AS15: 14.243717 | AT15: 25.915344 | AU15: 13.804174 | AV15: 25.040289 | AW15: 45.48511 | AX15: 50.212315 | AY15: 48.012697 | AZ15: 61.222061 | BA15: 69.298988 | BB15: 81.668256 | BC15: 67.275111 | BD15: 86.652688 | BE15: 74.428835 | BF15: 97.690476 | BG15: 117.36514 | BH15: 131.5976 | BI15: 78.841257 | BJ15: 111.09758 | BK15: 129.0708 | BL15: 216.67103 | BM15: 175.24219 | BN15: 225.87368 | BO15: 220.40423 | BP15: 255.79515 | BQ15: 235.478 | BR15: 223.07166 | BS15: 249.40501 | BT15: 251.13206 | BU15: 229.64024 | BV15: 106 | BW15: 102 | BX15: 190 | BY15: 175 | BZ15: 231 | CA15: 230 | CB15: 610 | CC15: 407.78192 | CD15: 427.53896 | CE15: 452.85158 | CF15: 479.92265 | CG15: 508.51822 | CH15: 539.99944 | CI15: 572.3124 | CJ15: 601.4735 | CK15: 635.69381 | CL15: 672.29458 | CM15: 714.45236 | CN15: 761.42521 | CO15: 812.06066 | CP15: 863.28101 | CQ15: 916.17274 | CR15: 976.12201 | CS15: 1033.9368 | CT15: 1097.1384 | CU15: 1164.3372 | CV15: 1237.7571 | CW15: 1312.3007 | CX15: 1390.3676 | CY15: 1481.3532 | CZ15: 1568.1457 | DA15: 1659.922 | DB15: 1760.8334 | DC15: 1866.4894 | DD15: 1977.7433 | DE15: 2095.1484 | DF15: 2218.6437 | DG15: 2341.7092 | DH15: 2483.0403 | DI15: 2624.7461 | DJ15: 2763.4145 | DK15: 2925.797 | DL15: 3085.4358 | DM15: 3261.3264 | DN15: 3438.8581 | DO15: 3622.9233 | DP15: 3820.871 | DQ15: 4021.391 | DR15: 4236.6268 | DS15: 4448.4509 | DT15: 4657.356 | DU15: 4880.4286 | DV15: 5109.7718 | DW15: 5357.8157 | DX15: 5594.7674 | DY15: 5821.5183 | DZ15: 6073.0409 | EA15: 6297.4139 | EB15: 6533.1861 | EC15: 6740.538 | ED15: 6982.9564 | EE15: 7213.9262 | EF15: 7434.0328 | EG15: 7644.6952 | EH15: 7847.3455 | EI15: 8044.5757 | EJ15: 8258.0688 | EK15: 8410.18 | EL15: 8548.4106 | EM15: 8712.4929 | EN15: 8826.1301 | EO15: 8962.6914 | EP15: 9059.4761 | EQ15: 9141.2566 | ER15: 9178.3848 | ES15: 9235.6949 | ET15: 9289.2474 | EU15: 9298.9481 | EV15: 9349.6053 | EW15: 9318.6974 | EX15: 9300.3403 | EY15: 9220.5584 | EZ15: 9218.4011 | FA15: 9171.0442
... A179: Zimbabwe | B179: ZWE | C179: =VLOOKUP(B179,CountryCodes!$B$4:$C$179,2,FALSE) -> AFZ | D179: Total | E179: End-use steel consumption [kt] | F179: EUSC | G179: kt | H179: 46.369207 | I179: 53.815409 | J179: 53.501316 | K179: 51.308891 | L179: 77.845836 | M179: 82.052885 | N179: 103.46675 | O179: 105.3611 | P179: 98.498305 | Q179: 119.69639 | R179: 237.05541 | S179: 256.66969 | T179: 252.91413 | U179: 307.62723 | V179: 248.39326 | W179: 205.60552 | X179: 152.77852 | Y179: 166.98879 | Z179: 217.41521 | AA179: 226.58596 | AB179: 279.60735 | AC179: 356.03928 | AD179: 376.70885 | AE179: 371.85565 | AF179: 387.13289 | AG179: 560.16519 | AH179: 563.7962 | AI179: 636.65247 | AJ179: 600.69421 | AK179: 630.9717 | AL179: 523.20767 | AM179: 379.21809 | AN179: 416.50646 | AO179: 161.5376 | AP179: 355.331 | AQ179: 337.26323 | AR179: 393.90318 | AS179: 289.54182 | AT179: 335.92707 | AU179: 259.34055 | AV179: 216.17941 | AW179: 213.35029 | AX179: 28.203958 | AY179: 231.24067 | AZ179: 323.19291 | BA179: 385.28267 | BB179: 389.61571 | BC179: 494.73288 | BD179: 356.86395 | BE179: 221.81367 | BF179: 127.75622 | BG179: 182.95183 | BH179: 126.6887 | BI179: 30.537429 | BJ179: 54.041426 | BK179: 70.188295 | BL179: 92.516457 | BM179: 117.80027 | BN179: 203.97938 | BO179: 545.5802 | BP179: 570.38443 | BQ179: 614.73967 | BR179: 634.228 | BS179: 592.50971 | BT179: 625.8706 | BU179: 345.33896 | BV179: 129 | BW179: 153 | BX179: 135 | BY179: 146 | BZ179: 154 | CA179: 175 | CB179: 651 | CC179: 661.31032 | CD179: 720.48219 | CE179: 751.14119 | CF179: 775.85099 | CG179: 801.55755 | CH179: 827.371 | CI179: 855.38155 | CJ179: 875.25493 | CK179: 900.60333 | CL179: 933.44474 | CM179: 965.24865 | CN179: 985.37756 | CO179: 1030.5047 | CP179: 1052.5573 | CQ179: 1087.8548 | CR179: 1123.4758 | CS179: 1152.6477 | CT179: 1189.9257 | CU179: 1240.2211 | CV179: 1246.8414 | CW179: 1302.1021 | CX179: 1316.3227 | CY179: 1356.4869 | CZ179: 1389.9959 | DA179: 1420.2981 | DB179: 1468.8838 | DC179: 1502.0341 | DD179: 1551.8478 | DE179: 1602.756 | DF179: 1628.8649 | DG179: 1677.2672 | DH179: 1693.8027 | DI179: 1748.1769 | DJ179: 1769.8042 | DK179: 1831.9014 | DL179: 1863.3227 | DM179: 1904.6631 | DN179: 1953.8496 | DO179: 2021.2747 | DP179: 2075.8864 | DQ179: 2127.6172 | DR179: 2156.0585 | DS179: 2237.199 | DT179: 2273.7063 | DU179: 2345.4426 | DV179: 2390.7157 | DW179: 2454.5457 | DX179: 2501.1385 | DY179: 2560.3071 | DZ179: 2658.949 | EA179: 2717.6796 | EB179: 2754.8211 | EC179: 2810.4606 | ED179: 2886.887 | EE179: 2940.0957 | EF179: 2986.3091 | EG179: 3055.6362 | EH179: 3120.3997 | EI179: 3176.0074 | EJ179: 3207.3322 | EK179: 3282.4682 | EL179: 3339.0235 | EM179: 3386.8171 | EN179: 3458.8861 | EO179: 3517.3974 | EP179: 3514.0859 | EQ179: 3603.0986 | ER179: 3665.0926 | ES179: 3665.3675 | ET179: 3736.33 | EU179: 3728.3412 | EV179: 3854.142 | EW179: 3884.4265 | EX179: 3874.7409 | EY179: 3930.1899 | EZ179: 3949.5271 | FA179: 3945.2465
A180: Global | B180: Global | D180: Total | E180: End-use steel consumption [kt] | F180: EUSC | G180: kt | H180: 132648.39 | I180: 129370.59 | J180: 147540.13 | K180: 134183.44 | L180: 170888.31 | M180: 178697.54 | N180: 185662.24 | O180: 170966.52 | P180: 201332.89 | Q180: 235027.47 | R180: 231254.4 | S180: 231940.54 | T180: 250912.26 | U180: 293914.44 | V180: 312760.9 | W180: 327969.71 | X180: 330947 | Y180: 367433.11 | Z180: 423369.3 | AA180: 449128.99 | AB180: 430425.57 | AC180: 465373.1 | AD180: 520807.48 | AE180: 516328.59 | AF180: 468329.02 | AG180: 495556.05 | AH180: 491001.71 | AI180: 524082.21 | AJ180: 548229.94 | AK180: 520573.81 | AL180: 510603.07 | AM180: 457426.81 | AN180: 473630.83 | AO180: 511063.6 | AP180: 534839.26 | AQ180: 527492.27 | AR180: 531173.7 | AS180: 562131.84 | AT180: 563204.01 | AU180: 555522.53 | AV180: 524630.31 | AW180: 518702.18 | AX180: 526142.55 | AY180: 543238.93 | AZ180: 554051.44 | BA180: 572862.63 | BB180: 594338.1 | BC180: 571261.77 | BD180: 579793 | BE180: 608462.41 | BF180: 610906.88 | BG180: 651162.21 | BH180: 705869.95 | BI180: 773285.24 | BJ180: 849090.68 | BK180: 932464.93 | BL180: 1009446.5 | BM180: 1003633.1 | BN180: 925958.21 | BO180: 1081810.1 | BP180: 1156163.3 | BQ180: 1173997.5 | BR180: 1241533 | BS180: 1258789.4 | BT180: 1207768.9 | BU180: 1247978.1 | BV180: 1604265.4 | BW180: 1674362.7 | BX180: 1725778.7 | BY180: 1800546.6 | BZ180: 1853805.7 | CA180: 1792375 | CB180: 1788695.8 | CC180: 1721500.8 | CD180: 1733865.4 | CE180: 1735492.1 | CF180: 1734921.7 | CG180: 1721957.9 | CH180: 1701936.2 | CI180: 1678593.3 | CJ180: 1658821.1 | CK180: 1643646 | CL180: 1635591.4 | CM180: 1630424.6 | CN180: 1629994.7 | CO180: 1632784.6 | CP180: 1642142.5 | CQ180: 1658970.5 | CR180: 1684664.4 | CS180: 1715791.4 | CT180: 1754821.5 | CU180: 1798288.3 | CV180: 1846308.3 | CW180: 1895158.6 | CX180: 1947514.4 | CY180: 2000539.1 | CZ180: 2054443.3 | DA180: 2108658.8 | DB180: 2161930.2 | DC180: 2213160.6 | DD180: 2264734 | DE180: 2312900.3 | DF180: 2358982.4 | DG180: 2402995.2 | DH180: 2442521.7 | DI180: 2479324.9 | DJ180: 2512021.8 | DK180: 2540478.8 | DL180: 2562168 | DM180: 2577373 | DN180: 2586548.7 | DO180: 2590691.3 | DP180: 2589822.8 | DQ180: 2584049.5 | DR180: 2571656.8 | DS180: 2557040.5 | DT180: 2540736.9 | DU180: 2521150.5 | DV180: 2499819.1 | DW180: 2478771.5 | DX180: 2457054.4 | DY180: 2437239.9 | DZ180: 2415969.6 | EA180: 2397075.3 | EB180: 2379355.4 | EC180: 2363473.8 | ED180: 2348946.4 | EE180: 2334192.8 | EF180: 2323512.4 | EG180: 2313511.8 | EH180: 2306032.1 | EI180: 2301648 | EJ180: 2296886.8 | EK180: 2300608.7 | EL180: 2304633.6 | EM180: 2309200.9 | EN180: 2314797.9 | EO180: 2320894 | EP180: 2328110.2 | EQ180: 2333577.8 | ER180: 2338992.1 | ES180: 2346293 | ET180: 2351518.2 | EU180: 2357025.7 | EV180: 2361078.6 | EW180: 2365346.3 | EX180: 2372944.4 | EY180: 2381332.2 | EZ180: 2388379.6 | FA180: 2395933.3
A181: Global | B181: Global | D181: Automotive | E181: End-use steel consumption [kt] | F181: EUSC | G181: kt | H181: 15560.469 | I181: 13991.607 | J181: 16771.403 | K181: 13384.553 | L181: 19759.405 | M181: 20990.228 | N181: 22055.516 | O181: 18416.043 | P181: 23109.367 | Q181: 29040.863 | R181: 29978.365 | S181: 30897.129 | T181: 34957.775 | U181: 43327.008 | V181: 46896.386 | W181: 49107.98 | X181: 50258.9 | Y181: 56028.794 | Z181: 63990.237 | AA181: 67187.731 | AB181: 63823.609 | AC181: 69659.455 | AD181: 78244.859 | AE181: 78043.866 | AF181: 69083.989 | AG181: 74537.08 | AH181: 73406.115 | AI181: 78228.307 | AJ181: 82138.264 | AK181: 76654.623 | AL181: 76623.68 | AM181: 66218.626 | AN181: 68810.313 | AO181: 74441.085 | AP181: 75615.412 | AQ181: 74487.977 | AR181: 76321.092 | AS181: 82375.137 | AT181: 81955.25 | AU181: 80602.312 | AV181: 73776.891 | AW181: 70753.341 | AX181: 68576.825 | AY181: 71055.796 | AZ181: 74223.641 | BA181: 75897.308 | BB181: 79421.352 | BC181: 76856.455 | BD181: 76805.126 | BE181: 82749.409 | BF181: 79461.736 | BG181: 82384.779 | BH181: 86971.643 | BI181: 96751.458 | BJ181: 104425.15 | BK181: 116482.95 | BL181: 125406.22 | BM181: 122252.14 | BN181: 98822.839 | BO181: 119606.15 | BP181: 127222.72 | BQ181: 129368.13 | BR181: 133314.1 | BS181: 138971.94 | BT181: 135644.78 | BU181: 142422.5 | BV181: 182277.46 | BW181: 192532.05 | BX181: 197055 | BY181: 193831.26 | BZ181: 218594.07 | CA181: 210891.95 | CB181: 202486.7 | CC181: 190782.7 | CD181: 193714.63 | CE181: 197630.45 | CF181: 202805.53 | CG181: 209434.01 | CH181: 217042.96 | CI181: 225237.68 | CJ181: 233470.5 | CK181: 240963.21 | CL181: 247213.07 | CM181: 251801.53 | CN181: 255043.65 | CO181: 257267.24 | CP181: 259349.89 | CQ181: 261791.27 | CR181: 265005.45 | CS181: 269175.62 | CT181: 274345.31 | CU181: 280304.66 | CV181: 286783.88 | CW181: 293263.49 | CX181: 299566.58 | CY181: 305270.81 | CZ181: 310243.31 | DA181: 314395.38 | DB181: 317893.85 | DC181: 320782.34 | DD181: 323566.59 | DE181: 326194.7 | DF181: 328965.87 | DG181: 331970.33 | DH181: 335096.5 | DI181: 338491.77 | DJ181: 342014.78 | DK181: 345579.37 | DL181: 348964.41 | DM181: 352093.22 | DN181: 354969.93 | DO181: 357637.09 | DP181: 360157.64 | DQ181: 362566.24 | DR181: 364805.9 | DS181: 367175.67 | DT181: 369769.52 | DU181: 372386.65 | DV181: 375151.06 | DW181: 378098.65 | DX181: 381086.03 | DY181: 384270.71 | DZ181: 387305.99 | EA181: 390423.67 | EB181: 393485.66 | EC181: 396581.73 | ED181: 399641.73 | EE181: 402583.15 | EF181: 405746.33 | EG181: 408889.39 | EH181: 412149.64 | EI181: 415593.87 | EJ181: 418938.18 | EK181: 422417.97 | EL181: 425940.89 | EM181: 429434.82 | EN181: 432937.58 | EO181: 436415.12 | EP181: 439847.07 | EQ181: 443011.89 | ER181: 446012.64 | ES181: 449068.16 | ET181: 451869.12 | EU181: 454444.09 | EV181: 456811 | EW181: 459089.2 | EX181: 461141.45 | EY181: 463068.69 | EZ181: 464712.47 | FA181: 466219.73
A182: Global | B182: Global | D182: Construction | E182: End-use steel consumption [kt] | F182: EUSC | G182: kt | H182: 87487.435 | I182: 86499.977 | J182: 96489.895 | K182: 89752.21 | L182: 109255.8 | M182: 113604.12 | N182: 117047.21 | O182: 109388.79 | P182: 125555.1 | Q182: 143465.49 | R182: 140104.97 | S182: 139256.67 | T182: 148954.26 | U182: 171221.88 | V182: 180874.52 | W182: 188370.77 | X182: 185950.59 | Y182: 206540.63 | Z182: 237617.02 | AA182: 251877.43 | AB182: 240441.05 | AC182: 257148.85 | AD182: 286550.03 | AE182: 282293.26 | AF182: 255447.22 | AG182: 266595.23 | AH182: 264972.15 | AI182: 282144.4 | AJ182: 295001.8 | AK182: 280042.81 | AL182: 271417.29 | AM182: 242772.55 | AN182: 249073.76 | AO182: 268568.53 | AP182: 282652.75 | AQ182: 276265.97 | AR182: 275666.02 | AS182: 291036.04 | AT182: 293480.59 | AU182: 290067.98 | AV182: 278064.53 | AW182: 273417.08 | AX182: 286815.61 | AY182: 299799.67 | AZ182: 303571.54 | BA182: 318217.8 | BB182: 331768.82 | BC182: 320383.89 | BD182: 326360.08 | BE182: 338046.95 | BF182: 343262.02 | BG182: 368764.32 | BH182: 401811.59 | BI182: 439545.62 | BJ182: 484302.6 | BK182: 531068.25 | BL182: 575398.74 | BM182: 577183.28 | BN182: 553159.58 | BO182: 631977.51 | BP182: 672097.65 | BQ182: 683842.89 | BR182: 730684.72 | BS182: 737610.26 | BT182: 705699.16 | BU182: 725775.6 | BV182: 930486.33 | BW182: 967495.79 | BX182: 997732.72 | BY182: 1060758 | BZ182: 1049008.6 | CA182: 1014627.8 | CB182: 1036320.7 | CC182: 996916.64 | CD182: 983074.24 | CE182: 963638.43 | CF182: 948524.65 | CG182: 920947.53 | CH182: 889365.76 | CI182: 854703.13 | CJ182: 820949.94 | CK182: 788888.94 | CL182: 762144.39 | CM182: 739218.9 | CN182: 722567.84 | CO182: 711206.51 | CP182: 706465.66 | CQ182: 708103.92 | CR182: 716542.21 | CS182: 728585.71 | CT182: 747100.64 | CU182: 769716.45 | CV182: 796913.74 | CW182: 825835.71 | CX182: 858582.9 | CY182: 892923.5 | CZ182: 928923.69 | DA182: 966525.06 | DB182: 1004453.3 | DC182: 1042240.3 | DD182: 1081127.6 | DE182: 1118145.4 | DF182: 1153724.1 | DG182: 1187603.1 | DH182: 1217871 | DI182: 1245662.7 | DJ182: 1269838.4 | DK182: 1290181.6 | DL182: 1304645.4 | DM182: 1313068.3 | DN182: 1315787.9 | DO182: 1313485.4 | DP182: 1305993.7 | DQ182: 1293381.1 | DR182: 1274462.9 | DS182: 1252650.6 | DT182: 1228332.4 | DU182: 1200730.1 | DV182: 1171016.6 | DW182: 1141163.4 | DX182: 1110591.4 | DY182: 1081423.8 | DZ182: 1051387 | EA182: 1023599.5 | EB182: 997205.6 | EC182: 972783.92 | ED182: 949908.56 | EE182: 927497.75 | EF182: 908692.96 | EG182: 890980.72 | EH182: 875629.51 | EI182: 863044.32 | EJ182: 850486.99 | EK182: 846131.6 | EL182: 841970.39 | EM182: 838166.15 | EN182: 835131.02 | EO182: 832443.32 | EP182: 830722.96 | EQ182: 827644.54 | ER182: 824665.9 | ES182: 823090.39 | ET182: 819964.73 | EU182: 817538.95 | EV182: 814129.66 | EW182: 811048.44 | EX182: 811832.52 | EY182: 813665.01 | EZ182: 814944.39 | FA182: 816994.68
A183: Global | B183: Global | D183: Machinery | E183: End-use steel consumption [kt] | F183: EUSC | G183: kt | H183: 17539.546 | I183: 17480.635 | J183: 20576.04 | K183: 18821.312 | L183: 24708.488 | M183: 26063.196 | N183: 27055.983 | O183: 24467.88 | P183: 29056.948 | Q183: 34409.441 | R183: 34059.244 | S183: 34101.119 | T183: 36868.177 | U183: 43989.193 | V183: 47363.201 | W183: 50648.806 | X183: 51913.83 | Y183: 59333.163 | Z183: 70016.575 | AA183: 75971.743 | AB183: 73841.369 | AC183: 80259.96 | AD183: 90373.246 | AE183: 90163.252 | AF183: 83059.893 | AG183: 87751.419 | AH183: 87302.618 | AI183: 92847.471 | AJ183: 97208.121 | AK183: 93343.655 | AL183: 92421.333 | AM183: 84913.633 | AN183: 88546.201 | AO183: 95564.11 | AP183: 100282.66 | AQ183: 100520.6 | AR183: 102869.44 | AS183: 109770.02 | AT183: 110939 | AU183: 110395.51 | AV183: 104960.24 | AW183: 102063.26 | AX183: 102223.75 | AY183: 102847.82 | AZ183: 104954.2 | BA183: 106188.34 | BB183: 109090.12 | BC183: 104388.76 | BD183: 104956.43 | BE183: 111412.51 | BF183: 111259.6 | BG183: 117518.96 | BH183: 127030.62 | BI183: 138450.82 | BJ183: 150957.74 | BK183: 164395.56 | BL183: 177633.16 | BM183: 176938.16 | BN183: 159235.47 | BO183: 184858.32 | BP183: 199312.77 | BQ183: 201604.46 | BR183: 211074.16 | BS183: 214544.49 | BT183: 206863.97 | BU183: 212875.51 | BV183: 260487.82 | BW183: 271319.3 | BX183: 276457.52 | BY183: 279879.1 | BZ183: 304138.08 | CA183: 292839.78 | CB183: 281605.61 | CC183: 267419.56 | CD183: 273679.7 | CE183: 278206.03 | CF183: 281065.23 | CG183: 284551.76 | CH183: 287707.06 | CI183: 291087.98 | CJ183: 295023.79 | CK183: 299678.39 | CL183: 305344.66 | CM183: 311656.05 | CN183: 318702.23 | CO183: 325870.94 | CP183: 333264.27 | CQ183: 340457.78 | CR183: 347270.59 | CS183: 353619.77 | CT183: 359564.95 | CU183: 365138.1 | CV183: 370487.7 | CW183: 375416.52 | CX183: 380200.51 | CY183: 384623.9 | CZ183: 388852.35 | DA183: 392793.73 | DB183: 396648.02 | DC183: 400099.15 | DD183: 403596.51 | DE183: 406654.85 | DF183: 409556.47 | DG183: 412313.59 | DH183: 414702.32 | DI183: 417061.69 | DJ183: 419342.53 | DK183: 421601.19 | DL183: 423668.42 | DM183: 425749.12 | DN183: 427763.68 | DO183: 429906.61 | DP183: 432159.43 | DQ183: 434524.61 | DR183: 436716.58 | DS183: 439130.2 | DT183: 441766.71 | DU183: 444298 | DV183: 446815.09 | DW183: 449392.67 | DX183: 451897.46 | DY183: 454566.59 | DZ183: 456958.98 | EA183: 459414.76 | EB183: 461849.34 | EC183: 464255.79 | ED183: 466623.07 | EE183: 468727.98 | EF183: 471099.06 | EG183: 473293.39 | EH183: 475606.36 | EI183: 478037.43 | EJ183: 480252.72 | EK183: 482550.15 | EL183: 484816.81 | EM183: 487122.69 | EN183: 489436.94 | EO183: 491679.6 | EP183: 493911.72 | EQ183: 495868.78 | ER183: 497609.87 | ES183: 499454.31 | ET183: 500991.75 | EU183: 502290.25 | EV183: 503296.05 | EW183: 504245.91 | EX183: 504969.44 | EY183: 505597.9 | EZ183: 505968.29 | FA183: 506325.04
A184: Global | B184: Global | D184: Other transportation equipment | E184: End-use steel consumption [kt] | F184: EUSC | G184: kt | H184: 7761.2024 | I184: 7881.2377 | J184: 9078.1904 | K184: 8728.4876 | L184: 10822.812 | M184: 11458.213 | N184: 11948.321 | O184: 11541.582 | P184: 13436 | Q184: 15534.194 | R184: 15420.194 | S184: 15656.166 | T184: 16551.371 | U184: 18782.315 | V184: 20028.47 | W184: 21162.563 | X184: 22229.876 | Y184: 23639.395 | Z184: 25950.398 | AA184: 27442.252 | AB184: 27160.247 | AC184: 29338.967 | AD184: 32522.646 | AE184: 32990.353 | AF184: 31084.417 | AG184: 32855.002 | AH184: 32784.19 | AI184: 35106.502 | AJ184: 36406.777 | AK184: 35109.664 | AL184: 35028.3 | AM184: 32693.597 | AN184: 34242.331 | AO184: 36607.576 | AP184: 38634.249 | AQ184: 39040.565 | AR184: 39428.695 | AS184: 40989.452 | AT184: 40809.768 | AU184: 39326.112 | AV184: 35590.255 | AW184: 34032.976 | AX184: 32860.226 | AY184: 30838.08 | AZ184: 31296.673 | BA184: 31395.805 | BB184: 32799.09 | BC184: 31511.085 | BD184: 32097.722 | BE184: 33759.538 | BF184: 33792.67 | BG184: 35965.32 | BH184: 40202.33 | BI184: 44683.14 | BJ184: 50726.034 | BK184: 55883.646 | BL184: 61643.022 | BM184: 61065.125 | BN184: 56553.899 | BO184: 66600.72 | BP184: 74018.079 | BQ184: 74273.257 | BR184: 78962.576 | BS184: 78513.401 | BT184: 75211.733 | BU184: 77102.359 | BV184: 101551.16 | BW184: 100939.92 | BX184: 103182.36 | BY184: 106377.72 | BZ184: 109908.72 | CA184: 104571.36 | CB184: 100838.66 | CC184: 95738.319 | CD184: 98014.775 | CE184: 98484.411 | CF184: 95631.653 | CG184: 94944.022 | CH184: 94196.212 | CI184: 93574.919 | CJ184: 93250.794 | CK184: 93198.678 | CL184: 93641.732 | CM184: 94504.175 | CN184: 95901.11 | CO184: 97737.189 | CP184: 100055.8 | CQ184: 102766.53 | CR184: 105857.56 | CS184: 109130.28 | CT184: 112649.29 | CU184: 116186.4 | CV184: 119749.17 | CW184: 123070.5 | CX184: 126155.21 | CY184: 128753.05 | CZ184: 130855.76 | DA184: 132361.85 | DB184: 133232.34 | DC184: 133419.95 | DD184: 133086.68 | DE184: 132093.43 | DF184: 130624.53 | DG184: 128786.14 | DH184: 126608.61 | DI184: 124306.72 | DJ184: 121971.9 | DK184: 119764.43 | DL184: 117628.35 | DM184: 115753.61 | DN184: 114216.77 | DO184: 113058.98 | DP184: 112349.66 | DQ184: 112071.58 | DR184: 112132.25 | DS184: 112648.54 | DT184: 113591.82 | DU184: 114773.35 | DV184: 116163.59 | DW184: 117712.2 | DX184: 119332.84 | DY184: 121024.15 | DZ184: 122572.92 | EA184: 124017.84 | EB184: 125275.12 | EC184: 126317.2 | ED184: 127094.11 | EE184: 127523.21 | EF184: 127754.27 | EG184: 127684.93 | EH184: 127425.21 | EI184: 127036.02 | EJ184: 126436.41 | EK184: 125772.07 | EL184: 125050.65 | EM184: 124346.01 | EN184: 123763.85 | EO184: 123292.89 | EP184: 122919.41 | EQ184: 122666.09 | ER184: 122597.4 | ES184: 122757.09 | ET184: 122999.69 | EU184: 123348.92 | EV184: 123808.08 | EW184: 124318.96 | EX184: 124845.1 | EY184: 125416.95 | EZ184: 125867.47 | FA184: 126294.65
A185: Global | B185: Global | D185: Products | E185: End-use steel consumption [kt] | F185: EUSC | G185: kt | H185: 4299.7378 | I185: 3517.1341 | J185: 4624.5995 | K185: 3496.8724 | L185: 6341.8074 | M185: 6581.7783 | N185: 7555.2091 | O185: 7152.2294 | P185: 10175.473 | Q185: 12577.479 | R185: 11691.628 | S185: 12029.456 | T185: 13580.674 | U185: 16594.05 | V185: 17598.323 | W185: 18679.586 | X185: 20593.806 | Y185: 21891.126 | Z185: 25795.07 | AA185: 26649.832 | AB185: 25159.293 | AC185: 28965.87 | AD185: 33116.696 | AE185: 32837.859 | AF185: 29653.503 | AG185: 33817.312 | AH185: 32536.637 | AI185: 35755.532 | AJ185: 37474.979 | AK185: 35423.06 | AL185: 35112.464 | AM185: 30828.405 | AN185: 32958.225 | AO185: 35882.297 | AP185: 37654.182 | AQ185: 37177.158 | AR185: 36888.453 | AS185: 37961.179 | AT185: 36019.397 | AU185: 35130.613 | AV185: 32238.395 | AW185: 38435.521 | AX185: 35666.131 | AY185: 38697.564 | AZ185: 40005.389 | BA185: 41163.375 | BB185: 41258.725 | BC185: 38121.58 | BD185: 39573.637 | BE185: 42494.009 | BF185: 43130.864 | BG185: 46528.835 | BH185: 49853.766 | BI185: 53854.203 | BJ185: 58679.155 | BK185: 64634.523 | BL185: 69365.316 | BM185: 66194.425 | BN185: 58186.429 | BO185: 78767.381 | BP185: 83512.067 | BQ185: 84908.718 | BR185: 87497.396 | BS185: 89149.349 | BT185: 84349.257 | BU185: 89802.108 | BV185: 129462.64 | BW185: 142075.59 | BX185: 151351.13 | BY185: 159700.61 | BZ185: 172156.22 | CA185: 169444.09 | CB185: 167444.13 | CC185: 170643.54 | CD185: 185382.04 | CE185: 197532.81 | CF185: 206894.66 | CG185: 212080.61 | CH185: 213624.24 | CI185: 213989.57 | CJ185: 216126.12 | CK185: 220916.8 | CL185: 227247.59 | CM185: 233243.91 | CN185: 237779.85 | CO185: 240702.69 | CP185: 243006.92 | CQ185: 245851.04 | CR185: 249988.55 | CS185: 255280.06 | CT185: 261161.29 | CU185: 266942.65 | CV185: 272373.78 | CW185: 277572.4 | CX185: 283009.24 | CY185: 288967.86 | CZ185: 295568.24 | DA185: 302582.79 | DB185: 309702.71 | DC185: 316618.91 | DD185: 323356.63 | DE185: 329811.94 | DF185: 336111.43 | DG185: 342322.11 | DH185: 348243.29 | DI185: 353802.06 | DJ185: 358854.13 | DK185: 363352.19 | DL185: 367261.33 | DM185: 370708.78 | DN185: 373810.47 | DO185: 376603.21 | DP185: 379162.37 | DQ185: 381505.97 | DR185: 383539.2 | DS185: 385435.55 | DT185: 387276.52 | DU185: 388962.35 | DV185: 390672.81 | DW185: 392404.58 | DX185: 394146.65 | DY185: 395954.71 | DZ185: 397744.76 | EA185: 399619.45 | EB185: 401539.67 | EC185: 403535.19 | ED185: 405678.92 | EE185: 407860.68 | EF185: 410219.83 | EG185: 412663.35 | EH185: 415221.41 | EI185: 417936.31 | EJ185: 420772.5 | EK185: 423736.92 | EL185: 426854.85 | EM185: 430131.22 | EN185: 433528.49 | EO185: 437063.11 | EP185: 440709.08 | EQ185: 444386.53 | ER185: 448106.26 | ES185: 451923.01 | ET185: 455692.88 | EU185: 459403.54 | EV185: 463033.83 | EW185: 466643.84 | EX185: 470155.92 | EY185: 473583.67 | EZ185: 476886.95 | FA185: 480099.22
A186: Afghanistan | B186: AFG | C186: =VLOOKUP(B186,CountryCodes!$B$4:$C$179,2,FALSE) -> ASC | E186: Population | F186: POPN | H186: 7825.766 | I186: 7932.912 | J186: 8042.655 | K186: 8150.741 | L186: 8265.158 | M186: 8388.801 | N186: 8519.802 | O186: 8656.868 | P186: 8789.935 | Q186: 8948.604 | R186: 9121.483 | S186: 9306.683 | T186: 9502.129 | U186: 9706.845 | V186: 9921.791 | W186: 10150.226 | X186: 10382.564 | Y186: 10629.354 | Z186: 10884.489 | AA186: 11150.329 | AB186: 11429.926 | AC186: 11705.409 | AD186: 12001.983 | AE186: 12314.016 | AF186: 12624.237 | AG186: 12923.671 | AH186: 13196.031 | AI186: 13485.482 | AJ186: 13737.4 | AK186: 13573.734 | AL186: 12764.889 | AM186: 11110.273 | AN186: 10872.483 | AO186: 10963.481 | AP186: 11416.962 | AQ186: 11436.742 | AR186: 11403.405 | AS186: 11372.232 | AT186: 11674.364 | AU186: 12073.812 | AV186: 12017.508 | AW186: 12460.25 | AX186: 14097.697 | AY186: 15788.647 | AZ186: 16712.942 | BA186: 17418.729 | BB186: 18107.803 | BC186: 18796.38 | BD186: 19523.611 | BE186: 20251.958 | BF186: 20008.696 | BG186: 20559.918 | BH186: 22196.316 | BI186: 23269.782 | BJ186: 23851.525 | BK186: 24957.609 | BL186: 25890.58 | BM186: 25929.124 | BN186: 27036.12 | BO186: 27896.081 | BP186: 28672.096 | BQ186: 30023.32 | BR186: 31096.748 | BS186: 32148.66 | BT186: 33436.386 | BU186: 34227.141 | BV186: 35174.083 | BW186: 36203.786 | BX186: 37282.292 | BY186: 38429.95 | BZ186: 39708.008 | CA186: 40292.816 | CB186: 40864.868 | CC186: 42044.654 | CD186: 43250.33 | CE186: 44437.893 | CF186: 45656.244 | CG186: 46861.567 | CH186: 48079.582 | CI186: 49371.851 | CJ186: 50706.953 | CK186: 52045.049 | CL186: 53370.646 | CM186: 54717.862 | CN186: 56001.066 | CO186: 57293.399 | CP186: 58613.923 | CQ186: 59944.165 | CR186: 61251.511 | CS186: 62637.433 | CT186: 64058.308 | CU186: 65419.378 | CV186: 66701.061 | CW186: 68049.266 | CX186: 69358.651 | CY186: 70683.748 | CZ186: 72085.638 | DA186: 73426.983 | DB186: 74792.486 | DC186: 76238.717 | DD186: 77531.552 | DE186: 78778.551 | DF186: 80136.021 | DG186: 81507.771 | DH186: 82885.848 | DI186: 84271.925 | DJ186: 85689.38 | DK186: 87097.919 | DL186: 88449.166 | DM186: 89714.316 | DN186: 91011.156 | DO186: 92256.291 | DP186: 93606.968 | DQ186: 94945.273 | DR186: 96332.889 | DS186: 97715.613 | DT186: 98961.907 | DU186: 100192.6 | DV186: 101508.63 | DW186: 102757.15 | DX186: 104076.13 | DY186: 105238.08 | DZ186: 106434.25 | EA186: 107692.24 | EB186: 108838.79 | EC186: 109866.95 | ED186: 110932.82 | EE186: 112018.83 | EF186: 113009.8 | EG186: 114157.05 | EH186: 115190.54 | EI186: 116078.11 | EJ186: 116954.35 | EK186: 117802.72 | EL186: 118783.23 | EM186: 119665.32 | EN186: 120421.15 | EO186: 121295.36 | EP186: 122092.72 | EQ186: 122874.32 | ER186: 123734.68 | ES186: 124485.33 | ET186: 125223 | EU186: 125955.83 | EV186: 126657.95 | EW186: 127322.34 | EX186: 127973.18 | EY186: 128637.81 | EZ186: 129291.71 | FA186: 129940.52
